Workbook

Sheet כללי (0)
B4: כללי
B5: שם הגוף המונחה | C5: המרכז למיפוי ישראל (מפ"י)
B6: שם פרויקט | C6: פורטל לקוחות מפ"י — הוכחת היתכנות (POC)
B7: בעל המידע (Data Owner) הגורם אשר הוסמך לאוסף/ליצור ולעבד את המידע במערכת ואחראי באופן חוקי על שמירה והגנה על המידע בהתאם לתקנות החוקיות ורגולטוריות הנוגעות למידע | C7: מפ"י — אגף מיפוי וממ"ג ואגף גבולות בינלאומיים (לאישור סופי על ידי מפ"י)
B8: אחראי פרויקט (אדמיניסטרטיבי) | C8: להשלמה על ידי מפ"י
B9: סוג המערכת | C9: פורטל אינטרנטי ציבורי (Web) להנגשת מידע גאוגרפי, הזמנת מוצרים ופניות שירות
B10: תיאור קצר של התהליכים העסקיים שהמערכת ומידע משרתים | C10: הצגת קטלוג המוצרים והשירותים של מפ"י לציבור; הזמנה מקוונת של מפות נייר ומפות היסטוריות; פנייה לקבלת מידע מאגף הגבולות הבינלאומיים; מעקב הזמנות; וממשק ניהול תוכן ומוצרים (CMS) לעובדי מפ"י.
B12: גורמים מאשרים את ממצאי תהליך ניהול הסיכונים
B13: אישור מנחה
B14: ממונה תמ"ק
B15: יועץ משפטי
B16: ממונה הגנת פרטיות
B17: מנהל מערכות מידע (מנמ"ר)
B18: תאריך האישור
B19: מזהה חישוב (אוטומטי) | C19: =" מחשבון סיווג דאטה עבור " &C6&" "&TEXT(NOW(),"DD-MM-YYYY-HH:MM") -> מחשבון סיווג דאטה עבור 06-01-2025-11:00
B21: גורמים מאשרים את ממצאי תהליך ניהול הסיכונים

Sheet כשירות ארגונית (1)
B3: כשירות ארגונית לגופי תמ"ק
D4: תשובה | F4: ציון | G4: ציון מקסימלי | H4: תשובה 1 | I4: תשובה 2 | J4: תשובה 3 | K4: תשובה 4
B5: אסטרטגיה | C5: האם הנהלת הארגון מודעת לתהליך המעבר לענן? | D5: ההנהלה מודעת לתהליך הארגון של המעבר לענן, אך לא הוצגה בפניה תוכנית העבודה למעבר לענן | F5: =IF(D5=H5,0,IF(D5=I5,1,IF(D5=J5,2,"ERROR"))) -> 1 | G5: 2 | H5: הוצגה להנהלה תוכנית העבודה הארגוית של המעבר לענן | I5: ההנהלה מודעת לתהליך הארגון של המעבר לענן, אך לא הוצגה בפניה תוכנית העבודה למעבר לענן | J5: ההנהלה לא מוערבת בתהליך הארגון של המעבר לענן
C6: האם הוגדרה אסטאטגיה ארגונית למעבר לענן? | D6: כן | F6: =IF(D6=H6,0,IF(D6=I6,1,"ERROR")) -> 0 | G6: 1 | H6: כן | I6: לא
D8: תשובה
B9: ניהול סיכונים | C9: האם הארגון הריחיב את מתודולוגיית לניהול סיכוני סייבר בענן? | D9: כן, קיימת מתודלוגיה לניהול סיכונים בארגון שנבחנה ויש צוות ייעודי לניהול הסיכונים | F9: =IF(D9=H9,0,IF(D9=I9,1,IF(D9=J9,2,IF(D9=K9,3,"ERROR")))) -> 0 | G9: 3 | H9: כן, קיימת מתודלוגיה לניהול סיכונים בארגון שנבחנה ויש צוות ייעודי לניהול הסיכונים | I9: כן, קיימת מתודלוגיה לניהול סיכונים בארגון שנבחנה בפועל | J9: קיימת מתודלוגיה לניהול סיכונים בארגון, בשלבי בדיקה ראשוניים | K9: לא קיימת מתודולוגיית ניהול סיכונים בארגון
C10: כמות מערכות בארגון עלו לענן? | D10: בין 2-5 | F10: =IF(D10=H10,0,IF(D10=I10,1,IF(D10=J10,2,IF(D10=K10,10,"ERROR")))) -> 1 | G10: 10 | H10: מעל 5 | I10: בין 2-5 | J10: מערכת אחת | K10: זוהי המערכת הראשונה
D12: תשובה
B13: משאבי כ"א בתחום הענן | C13: האם ממונה התמ"ק עבר הכשרות לתחום הענן? | D13: לא | F13: =IF(D13=H13,0,IF(D13=I13,1,"ERROR")) -> 1 | G13: 1 | H13: כן | I13: לא
D15: תשובה
B16: ניהול פיננסי | C16: האם הוגדרה מדיניות כלכלת ענן בארגון בדגש אבטחת הסייבר? | D16: אין היכרות עם מדיניות כלכלת הענן | F16: =IF(D16=H16,0,IF(D16=I16,1,IF(D16=J16,2,IF(D16=K16,3,"ERROR")))) -> 3 | G16: 3 | H16: מדיניות כלכלת ענן ממומשת במלואה | I16: מדיניות כלכלת ענן נמצאת בשלבי יישום | J16: מדיניות כלכלת הענן נמצאת בשלבי למידה | K16: אין היכרות עם מדיניות כלכלת הענן
C17: האם לארגון הוגדר תקציב ייעודי להעלאת מערכת לענן הכוללת את התחומים הבאים: עלות כוח אדם, ארכיטקטורת הפרויקט, היבטי אבטחה, עלות שירותי הענן ושימוש בו? | D17: אין הקצאת תקציבים כלל לצורך מעבר\הקמת המערכת בענן | F17: =IF(D17=H17,0,IF(D17=I17,1,IF(D17=J17,2,"ERROR"))) -> 2 | G17: 2 | H17: קיים תקציב ייעודי למעבר\הקמת המערכת לענן | I17: לא קיים תקציב ייעודי, אך מוקצה תקציב בעת הצורך, באופן נקודתי | J17: אין הקצאת תקציבים כלל לצורך מעבר\הקמת המערכת בענן
D19: תשובה
B20: תהליכים ארגוניים נוספים לענן | C20: האם לארגון יש תשתיות לניטור ותפעול בתחום אבטחת מידע לסביבת הענן? | D20: קיים ניטור בארגון כולל חיבור לסוק | F20: =IF(D20=H20,0,IF(D20=I20,0,IF(D20=J20,0,IF(D20=K20,1,"ERROR")))) -> 0 | G20: 1 | H20: קיים מערכות ניטור פנימיות | I20: קיים ניטור צד ג' ( ספק חיצוני) | J20: קיים ניטור בארגון כולל חיבור לסוק | K20: לא קיים מערכת לניטור סביבת המערכת בענן

Sheet פרופיל מערכת (2)
C3: פרטי המערכת
D4: תשובה | F4: ציון | G4: ציון מקסימלי | H4: תשובה 1 | I4: תשובה 2 | J4: תשובה 3 | K4: תשובה 4
A5: Q2.1 | B5: מאפייני מידע | C5: מה אופן השימוש המתוכנן בנתונים בענן? | D5: הנגשת מידע ואפשרות לעדכון (עם יכולת אחסון מידע או גיבוי המידע) | F5: =IF(D5=H5,0,IF(D5=I5,1,IF(D5=J5,2,IF(D5=K5,3,"ERROR")))) -> 1 | G5: 3 | H5: הנגשת המידע להצגה בלבד | I5: הנגשת מידע ואפשרות לעדכון (עם יכולת אחסון מידע או גיבוי המידע) | J5: עדכון ואחסון המידע (או גיבוי המידע) בשילוב לימוד מכונה ML | K5: עדכון ואחסון המידע (או גיבוי המידע) בשילוב עיבוד המידע בזמן אמת או לימוד מכונה
A6: Q2.2 | C6: מה הוא סוג הנתונים במערכת? | D6: פיתוח או בדיקות (נתוני דמה) | F6: =IF(D6=H6,0,IF(D6=I6,1,IF(D6=J6,5,IF(D6=K6,3,"ERROR")))) -> 1 | G6: 5 | H6: פיתוח (נתוני דמה) | I6: פיתוח או בדיקות (נתוני דמה) | J6: פיתוח או בדיקות (נתוני אמת) | K6: בדיקות או ייצור (נתוני אמת)
A7: Q2.3 | C7: האם המידע ישמר בישראל? | D7: לא | F7: =IF(D7=H7,0,IF(D7=I7,1,IF(D7=J7,2,"ERROR"))) -> 0 | G7: 2 | H7: כן | I7: לא | J7: משולב בארץ ובחו"ל
A8: Q2.4 | C8: האם המידע יעובד בישראל | D8: לא | F8: =IF(D8=H8,0,IF(D8=I8,1,IF(D8=J8,2,"ERROR"))) -> 0 | G8: 2 | H8: כן | I8: לא | J8: משולב בארץ ובחו"ל
A9: Q2.5 | C9: משך האחסון המקסימלי של מידע בענן? | D9: אחסון ארוך תווך מעל 6 חודשים | F9: =IF(D9=H9,0,IF(D9=I9,1,IF(D9=J9,2,IF(D9=K9,3,"ERROR")))) -> 1 | G9: 3 | H9: אחסון לצורך עיבוד בלבד (עד יום) | I9: אחסון לתווך זמן קצר (ימים בודדים) | J9: אחסון לתווך בינוני (מספר שבועות עד 6 חודשים) | K9: אחסון ארוך תווך מעל 6 חודשים
A10: Q2.6 | C10: האם המידע יוצפן בתנועה? | D10: כן | F10: =IF(D10=H10,0,IF(D10=I10,10,"ERROR")) -> 10 | G10: 10 | H10: כן | I10: לא
A11: Q2.7 | C11: האם המידע במערכת יוצפן במנוחה? | D11: כן | F11: =IF(D11=H11,0,IF(D11=I11,10,"ERROR")) -> 10 | G11: 10 | H11: כן | I11: לא
A12: Q2.8 | C12: היכן ינוהלו מפתחות ההצפנה? | D12: בענן על ידי שירות ענן אוטומטי | F12: =IF(D12=H12,10,IF(D12=I12,5,IF(D12=J12,3,IF(D12=K12,0,"ERROR")))) -> 5 | G12: 10 | H12: בענן על ידי שירות ענן אוטומטי | I12: בענן על ידי גוף התמ"ק | J12: בשירות מנוהל חיצוני על ידי גוף התמ"ק | K12: באופן מקומי ברשת גוף התמ"ק על ידי גוף התמ"ק
D14: תשובה
A15: Q2.9 | B15: מאפייני מערכת | C15: האם המידע או המערכת מוגדרים כתמ"ק (מערכת שבגללה הגוף הוגדר תמ"ק) | D15: לא | F15: =IF(D15=H15,100,IF(D15=I15,0,"ERROR")) -> 100 | G15: 100 | H15: כן | I15: לא
A16: Q2.10 | C16: סביבות במערכת | D16: סביבת בדיקות וסביבת ייצור | F16: =IF(D16=H16,0,IF(D16=I16,1,IF(D16=J16,2,IF(D16=K16,3,"ERROR")))) -> 0 | G16: 3 | H16: סביבות פיתוח | I16: סביבת פיתוח או בדיקות | J16: סביבת בדיקות וסביבת ייצור | K16: סביבת ייצור בלבד
A17: Q2.11 | C17: זמינות המערכת (SLA) דרושה | D17: כסף 99.9% - עד 9 שעות השבתה בשנה | F17: =IF(D17=H17,0,IF(D17=I17,1,IF(D17=J17,2,IF(D17=K17,3,"ERROR")))) -> 1 | G17: 3 | H17: זמינות Best Effort | I17: כסף 99.9% - עד 9 שעות השבתה בשנה | J17: זהב 99.99% - עד 1 שעת השבתה בשנה | K17: פלטינה 99.999% - פחות מ 6 דקות השבתה בשנה
A18: Q2.12 | C18: מידת הפגיעה בשירותי זמן אמת (Real Time Services) כתוצאה מפגיעה במערכת | D18: השפעה נמוכה מאוד על שירות לא אסטרטגי | F18: =IF(D18=H18,0,IF(D18=I18,1,IF(D18=J18,2,IF(D18=K18,3,"ERROR")))) -> 0 | G18: 3 | H18: השפעה נמוכה מאוד על שירות לא אסטרטגי | I18: חריגה של 1-3 יממות באספקת שירות לא אסטרטגי | J18: חריגה של עד מספר שעות לאספקת שירות אסטרטגי | K18: פגיעה ניכרת לאספקת שירות אסטרטגי בביקוש גבוהה
A19: Q2.13 | C19: מה מידת ההשפעה של פגיעה במערכת על גישה\הפעילות השוטפת של מערכות אחרות בארגון | D19: ללא פגיעה או השפעה על פעילות של מערכות פנימיות | F19: =IF(D19=H19,0,IF(D19=I19,1,IF(D19=J19,2,IF(D19=K19,3,"ERROR")))) -> 0 | G19: 3 | H19: ללא פגיעה או השפעה על פעילות של מערכות פנימיות | I19: פגיעה מצומצמת בפעילות השוטפת של מערכות פנימיות | J19: פגיעה חלקית ביכולת הגישה\הפעילות השוטפת של מערכות פנימיות קריטיות | K19: פגיעה מהותית ביכולת הגישה\הפעילות שוטפת של מערכות פנימיות קריטיות
A20: Q2.14 | C20: מידת השפעת פגיעה במערכת על תהליכים פיזיים OT (ניהול בניין, ניהול תהליך משני, ניהול תהליך ראשי) | D20: ללא השפעה או פגיעה בתהליך פיזי בארגון | F20: =IF(D20=H20,0,IF(D20=I20,1,IF(D20=J20,5,IF(D20=K20,10,"ERROR")))) -> 1 | G20: 10 | H20: ללא השפעה או פגיעה בתהליך פיזי בארגון | I20: פגיעה עקיפה לתהליך קבלת החלטות בנוגע לתהליך פיזי בארגון | J20: פגיעה עקיפה לתהליך קריטי בארגון | K20: פגיעה ישירה בתהליך ראשי פיזי (קינטי) קריטי לארגון
A21: Q2.15 | C21: מה היא תצורת השרידות של המערכת | D21: שרידות מלאה אוטומטית (גיבוי חם) | F21: =IF(D21=H21,0,IF(D21=I21,1,IF(D21=J21,2,IF(D21=K21,3,"ERROR")))) -> 0 | G21: 3 | H21: שרידות מלאה אוטומטית (גיבוי חם) | I21: שרידות מלאה ידנית | J21: שרידות חלקית אוטומטית | K21: שרידות חלקית ידנית
A22: Q2.16 | C22: מה מידת ההשפעה של פגיעה במערכת על ניהול התשתיות הטכנולוגיות בחברה (ניטור, ממשק ניהול, API, רשת,גיבויים וכו) | D22: ללא השפעה על פעילות מערכות ניהול תשתיות | F22: =IF(D22=H22,0,IF(D22=I22,1,IF(D22=J22,2,IF(D22=K22,3,"ERROR")))) -> 0 | G22: 3 | H22: ללא השפעה על פעילות מערכות ניהול תשתיות | I22: פגיעה חלקית בפונקציונליות של מערכת בודדת לניהול תשתיות לא קריטיות | J22: פגיעה מצומצמת למערכת ניהול תשתיות קריטיות | K22: פגיעה רוחבית למערכת ניהול תשתיות קריטיות
A23: Q2.17 | C23: סוג הגישה למערכת | D23: Web או מובייל או אפליקציה מהאינטרנט | F23: =IF(D23=H23,0,IF(D23=I23,1,IF(D23=J23,2,IF(D23=K23,3,"ERROR")))) -> 0 | G23: 3 | H23: WEB מתוך הארגון בלבד | I23: אפליקציה ייעודית ברשת הארגון | J23: מובייל או אפליקציה מהאינטרנט או מהארגון | K23: Web או מובייל או אפליקציה מהאינטרנט
D25: תשובה
A26: Q2.18 | B26: משתמשים והזדהות | C26: פרטו לגבי פרופילים אופייניים של המשתמשים במערכת | D26: חיצוניים | F26: =IF(D26=H26,0,IF(D26=I26,1,IF(D26=J26,2,IF(D26=K26,3,"ERROR")))) -> 2 | G26: 3 | H26: מנהלים פנימיים בלבד | I26: פנימיים | J26: חיצוניים | K26: אורחים
A27: Q2.19 | C27: מהו היקף המשתמשים הצפוי / קיים? | D27: מעל 100 משתמשים | F27: =IF(D27=H27,0,IF(D27=I27,1,IF(D27=J27,2,IF(D27=K27,3,"ERROR")))) -> 1 | G27: 3 | H27: בודדים עד 5 משתמשים | I27: בין 5-50 משתמשים | J27: בין 50-100 משתמשים | K27: מעל 100 משתמשים
A28: Q2.20 | C28: מהם תהליכי ההזדהות למערכת (עבור משתמשים) | D28: שם משתמש וסיסמא | F28: =IF(D28=H28,0,IF(D28=I28,1,IF(D28=J28,2,IF(D28=K28,3,"ERROR")))) -> 1 | G28: 3 | H28: לא קיימת הזדהות | I28: הזדהות רב שלבית ארגונית | J28: התחברות SSO ציבורית\צד ג' | K28: שם משתמש וסיסמא
A29: Q2.21 | C29: אופן הגישה למערכת (עבור משתמשים) | D29: המערכת נגישה במרשת האינטרנט עולמית ללא VPN | F29: =IF(D29=H29,0,IF(D29=I29,1,IF(D29=J29,2,IF(D29=K29,3,"ERROR")))) -> 0 | G29: 3 | H29: המערכת נגישה מסגמנט ייעודי ברשת הפנים ארגונית | I29: המערכת נגישה פנים ארגונית בלבד | J29: המערכת נגישה פנים ארגונית או באמצעות VPN | K29: המערכת נגישה במרשת האינטרנט עולמית ללא VPN
A30: Q2.22 | C30: תצורת הגישה | D30: גישה אינטרנטית WEB | F30: =IF(D30=H30,0,IF(D30=I30,1,IF(D30=J30,2,IF(D30=K30,3,"ERROR")))) -> 0 | G30: 3 | H30: גישה מבודלת על ידי מערכת אבטחה | I30: גישה API | J30: גישה בפורמט בסיס נתונים | K30: גישה אינטרנטית WEB
A31: Q2.23 | C31: כמות משתמשים פנימיים | D31: עשרות | F31: =IF(D31=H31,0,IF(D31=I31,1,IF(D31=J31,2,IF(D31=K31,3,"ERROR")))) -> 1 | G31: 3 | H31: לא קיימים משתמשים מסוג זה | I31: עשרות | J31: מאות | K31: אלפים ומעלה
A32: Q2.24 | C32: כמות משתמשים ספק חיצוני | D32: עשרות | F32: =IF(D32=H32,0,IF(D32=I32,1,IF(D32=J32,2,IF(D32=K32,3,"ERROR")))) -> 1 | G32: 3 | H32: לא קיימים משתמשים מסוג זה | I32: עשרות | J32: מאות | K32: אלפים ומעלה
A33: Q2.25 | C33: כמות משתמשים ציבוריים | D33: מאות | F33: =IF(D33=H33,0,IF(D33=I33,1,IF(D33=J33,2,IF(D33=K33,3,"ERROR")))) -> 0 | G33: 3 | H33: לא קיימים משתמשים מסוג זה | I33: עשרות | J33: מאות | K33: אלפים ומעלה
A34: Q2.26 | C34: אופן הגישה למערכת (עבור ניהול המערכת) | D34: שם משתמש וסיסמא - נותן שירות חיצוני ע"ג רשת האינטרנט | F34: =IF(D34=H34,0,IF(D34=I34,1,IF(D34=J34,2,IF(D34=K34,3,"ERROR")))) -> 0 | G34: 3 | H34: מערכת ייעודית לניהול מתוך הארגון בלבד או הזדהות רב שלבית ארגונית - ניהול פנימי לארגון | I34: התחברות SSO ארגונית - ניהול פנימי לארגון | J34: הזדהות רב שלבית חיצוני - נותן שירות חיצוני ע"ג רשת האינטרנט | K34: שם משתמש וסיסמא - נותן שירות חיצוני ע"ג רשת האינטרנט
D36: תשובה
A37: Q2.28 | B37: ממשקים | C37: כמות ממשקים לפנים הארגון | D37: לא רלוונטי / ללא ממשקים פנימיים | F37: =IF(D37=H37,0,IF(D37=I37,1,IF(D37=J37,2,IF(D37=K37,3,"ERROR")))) -> 0 | G37: 3 | H37: לא רלוונטי / ללא ממשקים פנימיים | I37: 1-2 ממשקים פנימים | J37: 2-10 ממשקים | K37: מעל 10 ממשקים
A38: Q2.29 | C38: כמות ממשקים חיצוניים (ביון הארגון לארגונים אחרים והחוצה) | D38: 2-10 ממשקים | F38: =IF(D38=H38,0,IF(D38=I38,1,IF(D38=J38,2,IF(D38=K38,3,"ERROR")))) -> 0 | G38: 3 | H38: לא רלוונטי / ללא ממשקים פנימיים | I38: 1-2 ממשקים פנימים | J38: 2-10 ממשקים | K38: מעל 10 ממשקים
A39: Q2.30 | C39: האם מבוצע תהליך זיכוי - הלבנה השחרה בממשקים | D39: לא מבוצע תהליך הלבנה\השחרה | F39: =IF(D39=H39,0,IF(D39=I39,1,IF(D39=J39,5,IF(D39=K39,10,"ERROR")))) -> 0 | G39: 10 | H39: לא רלוונטי / לא נדרש | I39: כן באופן מלא | J39: חלקי | K39: לא מבוצע תהליך הלבנה\השחרה
A40: Q2.31 | C40: תדירות הקישור לממשקים | D40: רב פעמית (עד 20 פעם ביום) | F40: =IF(D40=H40,0,IF(D40=I40,1,IF(D40=J40,2,IF(D40=K40,3,"ERROR")))) -> 0 | G40: 3 | H40: לא רלוונטי / לא נדרש | I40: רב פעמית (עד 20 פעם ביום) | J40: מרובה (20-50 פעם ביום) | K40: קבוע (מעל 50 פעם ביום)
A41: Q2.32 | C41: פרוטוקולים בשימוש הממשק | D41: פרוטוקול פומבי מוצפן | F41: =IF(D41=H41,0,IF(D41=I41,1,IF(D41=J41,2,IF(D41=K41,3,"ERROR")))) -> 0 | G41: 3 | H41: לא רלוונטי / פרוטוקול ייעודי מוצפן | I41: פרוטוקול פומבי מוצפן | J41: פרוטוקול ייעודי לא מוצפן | K41: פרוטוקול גלוי לא מוצפן
A42: Q2.33 | C42: האם מתקיימים ממשקי API מול מערכות מחוץ לשדרת המידע | D42: כן | F42: =IF(D42=H42,0,IF(D42=I42,1,"ERROR")) -> 0 | G42: 1 | H42: לא רלוונטי / לא קיים | I42: כן
A43: Q2.34 | C43: הסתמכות המערכת על ממשקי התקשרות חיצונית (תיבת מייל, CHAT BOT, וואצאפ\SMS נכנס, טעינה ועיבוד קבצים) | D43: חלק משני מפונקציונליות לא קריטית של המערכת מבוסס על העברת תוכן ממשקי התקשרות חיצוניים | F43: =IF(D43=H43,0,IF(D43=I43,1,IF(D43=J43,2,IF(D43=K43,3,"ERROR")))) -> 0 | G43: 3 | H43: לא רלוונטי / המערכת לא מתבססת על העברת תוכן ממשקי התקשרות חיצוניים | I43: חלק משני מפונקציונליות לא קריטית של המערכת מבוסס על העברת תוכן ממשקי התקשרות חיצוניים | J43: חלק ניכר מפעילות המערכת מתבסס על העברת תוכן מממשקי התקשרות חיצוניים | K43: כלל פעילות המערכת מבוססת על העברת תוכן מממשקי התקשרות חיצוניים
D45: תשובה
A46: Q2.35 | B46: אופן היישום בענן | C46: אופן המגרציה לענן | D46: refactor | F46: =IF(D46=H46,0,IF(D46=I46,1,IF(D46=J46,2,IF(D46=K46,3,"ERROR")))) -> 0 | G46: 3 | H46: retire או tetain | I46: rehost | J46: replatform | K46: refactor
...

Sheet חישובים
A1: INF TYPE | B1: CP | C1: Chosen INF | D1: Language | E1: Count Controls | G1: Identify | H1: Detect | I1: Protect | J1: Respond | K1: Recover | N1: Cloud Provider | O1: Language | Q1: Yes | S1: כמות בקרות להם יש בקרת ספק | T1: כמות בקרות ספק שמוטמעות ב LZ | U1: כמות בקרות חד פעמיות
A2: הכל | B2: ='פרופיל בקרות דרוש (8)'!E3 -> GCP | C2: ='פרופיל בקרות דרוש (8)'!E2 -> IaaS | D2: ='פרופיל בקרות דרוש (8)'!E4 -> עברית - מקוצר | E2: =IF( AND($D$2=$O$2, $B$2=$N$2), COUNTIF('בקרות להפחתת סיכון AWS (EN)'!A:A,"Yes"), IF( AND($D$2=$O$3, $B$2=$N$2), COUNTIF('בקרות להפחתת סיכון AWS (HEB)'!A:A,"Yes"), IF( AND($D$2=$O$2, $B$2=$N$3), COUNTIF('בקרות להפחתת סיכון GCP (EN)'!A:A,"Yes"), IF( AND($D$2=$O$3, $B$2=$N$3), COUNTIF('בקרות להפחתת סיכון GCP (HEB)'!A:A,"Yes") ) ) ) ) -> 218 | F2: = | G2: =IF( AND($D$2=$O$2, $B$2=$N$2), COUNTIFS('בקרות להפחתת סיכון AWS (EN)'!$A:$A,"YES",'בקרות להפחתת סיכון AWS (EN)'!$E:$E,G1) & "/" & COUNTIF('בקרות להפחתת סיכון AWS (EN)'!$E:$E,G1), IF( AND($D$2=$O$3, $B$2=$N$2), COUNTIFS('בקרות להפחתת סיכון AWS (HEB)'!$A:$A,"YES",'בקרות להפחתת סיכון AWS (HEB)'!$E:$E,G1) & "/" & COUNTIF('בקרות להפחתת סיכון AWS (HEB)'!$E:$E,G1), IF( AND($D$2=$O$2, $B$2=$N$3), COUNTIFS('בקרות להפחתת סיכון GCP (EN)'!$A:$A,"YES",'בקרות להפחתת סיכון GCP (EN)'!$E:$E,G1) & "/" & COUNTIF('בקרות להפחתת סיכון GCP (EN)'!$E:$E,G1), IF( AND($D$2=$O$3, $B$2=$N$3), COUNTIFS('בקרות להפחתת סיכון GCP (HEB)'!$A:$A,"YES",'בקרות להפחתת סיכון GCP (HEB)'!$E:$E,G1) & "/" & COUNTIF('בקרות להפחתת סיכון GCP (HEB)'!$E:$E,G1) ) ) ) ) -> 20/21 | H2: =IF( AND($D$2=$O$2, $B$2=$N$2), COUNTIFS('בקרות להפחתת סיכון AWS (EN)'!$A:$A,"YES",'בקרות להפחתת סיכון AWS (EN)'!$E:$E,H1) & "/" & COUNTIF('בקרות להפחתת סיכון AWS (EN)'!$E:$E,H1), IF( AND($D$2=$O$3, $B$2=$N$2), COUNTIFS('בקרות להפחתת סיכון AWS (HEB)'!$A:$A,"YES",'בקרות להפחתת סיכון AWS (HEB)'!$E:$E,H1) & "/" & COUNTIF('בקרות להפחתת סיכון AWS (HEB)'!$E:$E,H1), IF( AND($D$2=$O$2, $B$2=$N$3), COUNTIFS('בקרות להפחתת סיכון GCP (EN)'!$A:$A,"YES",'בקרות להפחתת סיכון GCP (EN)'!$E:$E,H1) & "/" & COUNTIF('בקרות להפחתת סיכון GCP (EN)'!$E:$E,H1), IF( AND($D$2=$O$3, $B$2=$N$3), COUNTIFS('בקרות להפחתת סיכון GCP (HEB)'!$A:$A,"YES",'בקרות להפחתת סיכון GCP (HEB)'!$E:$E,H1) & "/" & COUNTIF('בקרות להפחתת סיכון GCP (HEB)'!$E:$E,H1) ) ) ) ) -> 47/49 | I2: =IF( AND($D$2=$O$2, $B$2=$N$2), COUNTIFS('בקרות להפחתת סיכון AWS (EN)'!$A:$A,"YES",'בקרות להפחתת סיכון AWS (EN)'!$E:$E,I1) & "/" & COUNTIF('בקרות להפחתת סיכון AWS (EN)'!$E:$E,I1), IF( AND($D$2=$O$3, $B$2=$N$2), COUNTIFS('בקרות להפחתת סיכון AWS (HEB)'!$A:$A,"YES",'בקרות להפחתת סיכון AWS (HEB)'!$E:$E,I1) & "/" & COUNTIF('בקרות להפחתת סיכון AWS (HEB)'!$E:$E,I1), IF( AND($D$2=$O$2, $B$2=$N$3), COUNTIFS('בקרות להפחתת סיכון GCP (EN)'!$A:$A,"YES",'בקרות להפחתת סיכון GCP (EN)'!$E:$E,I1) & "/" & COUNTIF('בקרות להפחתת סיכון GCP (EN)'!$E:$E,I1), IF( AND($D$2=$O$3, $B$2=$N$3), COUNTIFS('בקרות להפחתת סיכון GCP (HEB)'!$A:$A,"YES",'בקרות להפחתת סיכון GCP (HEB)'!$E:$E,I1) & "/" & COUNTIF('בקרות להפחתת סיכון GCP (HEB)'!$E:$E,I1) ) ) ) ) -> 132/139 | J2: =IF( AND($D$2=$O$2, $B$2=$N$2), COUNTIFS('בקרות להפחתת סיכון AWS (EN)'!$A:$A,"YES",'בקרות להפחתת סיכון AWS (EN)'!$E:$E,J1) & "/" & COUNTIF('בקרות להפחתת סיכון AWS (EN)'!$E:$E,J1), IF( AND($D$2=$O$3, $B$2=$N$2), COUNTIFS('בקרות להפחתת סיכון AWS (HEB)'!$A:$A,"YES",'בקרות להפחתת סיכון AWS (HEB)'!$E:$E,J1) & "/" & COUNTIF('בקרות להפחתת סיכון AWS (HEB)'!$E:$E,J1), IF( AND($D$2=$O$2, $B$2=$N$3), COUNTIFS('בקרות להפחתת סיכון GCP (EN)'!$A:$A,"YES",'בקרות להפחתת סיכון GCP (EN)'!$E:$E,J1) & "/" & COUNTIF('בקרות להפחתת סיכון GCP (EN)'!$E:$E,J1), IF( AND($D$2=$O$3, $B$2=$N$3), COUNTIFS('בקרות להפחתת סיכון GCP (HEB)'!$A:$A,"YES",'בקרות להפחתת סיכון GCP (HEB)'!$E:$E,J1) & "/" & COUNTIF('בקרות להפחתת סיכון GCP (HEB)'!$E:$E,J1) ) ) ) ) -> 12/12 | K2: =IF( AND($D$2=$O$2, $B$2=$N$2), COUNTIFS('בקרות להפחתת סיכון AWS (EN)'!$A:$A,"YES",'בקרות להפחתת סיכון AWS (EN)'!$E:$E,K1) & "/" & COUNTIF('בקרות להפחתת סיכון AWS (EN)'!$E:$E,K1), IF( AND($D$2=$O$3, $B$2=$N$2), COUNTIFS('בקרות להפחתת סיכון AWS (HEB)'!$A:$A,"YES",'בקרות להפחתת סיכון AWS (HEB)'!$E:$E,K1) & "/" & COUNTIF('בקרות להפחתת סיכון AWS (HEB)'!$E:$E,K1), IF( AND($D$2=$O$2, $B$2=$N$3), COUNTIFS('בקרות להפחתת סיכון GCP (EN)'!$A:$A,"YES",'בקרות להפחתת סיכון GCP (EN)'!$E:$E,K1) & "/" & COUNTIF('בקרות להפחתת סיכון GCP (EN)'!$E:$E,K1), IF( AND($D$2=$O$3, $B$2=$N$3), COUNTIFS('בקרות להפחתת סיכון GCP (HEB)'!$A:$A,"YES",'בקרות להפחתת סיכון GCP (HEB)'!$E:$E,K1) & "/" & COUNTIF('בקרות להפחתת סיכון GCP (HEB)'!$E:$E,K1) ) ) ) ) -> 7/7 | N2: AWS | O2: English - Brief | Q2: ** | S2: =IF( AND($D$2=$O$2, $B$2=$N$2), COUNTIFS('בקרות להפחתת סיכון AWS (EN)'!AA:AA,"v",'בקרות להפחתת סיכון AWS (EN)'!A:A,"Yes"), IF( AND($D$2=$O$3, $B$2=$N$2), COUNTIFS('בקרות להפחתת סיכון AWS (HEB)'!AA:AA,"v",'בקרות להפחתת סיכון AWS (HEB)'!A:A,"Yes"), IF( AND($D$2=$O$2, $B$2=$N$3), COUNTIFS('בקרות להפחתת סיכון GCP (EN)'!AA:AA,"v",'בקרות להפחתת סיכון GCP (EN)'!A:A,"Yes"), IF( AND($D$2=$O$3, $B$2=$N$3), COUNTIFS('בקרות להפחתת סיכון GCP (HEB)'!AA:AA,"v",'בקרות להפחתת סיכון GCP (HEB)'!A:A,"Yes") ) ) ) ) -> 105 | T2: =IF( AND($D$2=$O$2, $B$2=$N$2), COUNTIFS('בקרות להפחתת סיכון AWS (EN)'!AA:AA,"v",'בקרות להפחתת סיכון AWS (EN)'!U:U,"v",'בקרות להפחתת סיכון AWS (EN)'!A:A,"Yes"), IF( AND($D$2=$O$3, $B$2=$N$2), COUNTIFS('בקרות להפחתת סיכון AWS (HEB)'!AA:AA,"v",'בקרות להפחתת סיכון AWS (HEB)'!U:U,"v",'בקרות להפחתת סיכון AWS (HEB)'!A:A,"Yes"), IF( AND($D$2=$O$2, $B$2=$N$3), COUNTIFS('בקרות להפחתת סיכון GCP (EN)'!AA:AA,"v",'בקרות להפחתת סיכון GCP (EN)'!U:U,"v",'בקרות להפחתת סיכון GCP (EN)'!A:A,"Yes"), IF( AND($D$2=$O$3, $B$2=$N$3), COUNTIFS('בקרות להפחתת סיכון GCP (HEB)'!AA:AA,"v",'בקרות להפחתת סיכון GCP (HEB)'!U:U,"v",'בקרות להפחתת סיכון GCP (HEB)'!A:A,"Yes") ) ) ) ) -> 25 | U2: =IF( AND($D$2=$O$2, $B$2=$N$2), COUNTIFS('בקרות להפחתת סיכון AWS (EN)'!W:W,"ארגוני",'בקרות להפחתת סיכון AWS (EN)'!A:A,"Yes"), IF( AND($D$2=$O$3, $B$2=$N$2), COUNTIFS('בקרות להפחתת סיכון AWS (HEB)'!W:W,"ארגוני",'בקרות להפחתת סיכון AWS (HEB)'!A:A,"Yes"), IF( AND($D$2=$O$2, $B$2=$N$3), COUNTIFS('בקרות להפחתת סיכון GCP (EN)'!W:W,"ארגוני",'בקרות להפחתת סיכון GCP (EN)'!A:A,"Yes"), IF( AND($D$2=$O$3, $B$2=$N$3), COUNTIFS('בקרות להפחתת סיכון GCP (HEB)'!W:W,"ארגוני",'בקרות להפחתת סיכון GCP (HEB)'!A:A,"Yes") ) ) ) ) -> 124 | V2: ארגוני
A3: IaaS | G3: =IF( AND($D$2=$O$2, $B$2=$N$2), COUNTIFS('בקרות להפחתת סיכון AWS (EN)'!$A:$A, "Yes", 'בקרות להפחתת סיכון AWS (EN)'!$E:$E, G1), IF( AND($D$2=$O$3, $B$2=$N$2), COUNTIFS('בקרות להפחתת סיכון AWS (HEB)'!$A:$A, "Yes", 'בקרות להפחתת סיכון AWS (HEB)'!$E:$E, G1), IF( AND($D$2=$O$2, $B$2=$N$3), COUNTIFS('בקרות להפחתת סיכון GCP (EN)'!$A:$A, "Yes", 'בקרות להפחתת סיכון GCP (EN)'!$E:$E, G1), IF( AND($D$2=$O$3, $B$2=$N$3), COUNTIFS('בקרות להפחתת סיכון GCP (HEB)'!$A:$A, "Yes", 'בקרות להפחתת סיכון GCP (HEB)'!$E:$E, G1) ) ) ) ) -> 20 | H3: =IF( AND($D$2=$O$2, $B$2=$N$2), COUNTIFS('בקרות להפחתת סיכון AWS (EN)'!$A:$A, "Yes", 'בקרות להפחתת סיכון AWS (EN)'!$E:$E, H1), IF( AND($D$2=$O$3, $B$2=$N$2), COUNTIFS('בקרות להפחתת סיכון AWS (HEB)'!$A:$A, "Yes", 'בקרות להפחתת סיכון AWS (HEB)'!$E:$E, H1), IF( AND($D$2=$O$2, $B$2=$N$3), COUNTIFS('בקרות להפחתת סיכון GCP (EN)'!$A:$A, "Yes", 'בקרות להפחתת סיכון GCP (EN)'!$E:$E, H1), IF( AND($D$2=$O$3, $B$2=$N$3), COUNTIFS('בקרות להפחתת סיכון GCP (HEB)'!$A:$A, "Yes", 'בקרות להפחתת סיכון GCP (HEB)'!$E:$E, H1) ) ) ) ) -> 47 | I3: =IF( AND($D$2=$O$2, $B$2=$N$2), COUNTIFS('בקרות להפחתת סיכון AWS (EN)'!$A:$A, "Yes", 'בקרות להפחתת סיכון AWS (EN)'!$E:$E, I1), IF( AND($D$2=$O$3, $B$2=$N$2), COUNTIFS('בקרות להפחתת סיכון AWS (HEB)'!$A:$A, "Yes", 'בקרות להפחתת סיכון AWS (HEB)'!$E:$E, I1), IF( AND($D$2=$O$2, $B$2=$N$3), COUNTIFS('בקרות להפחתת סיכון GCP (EN)'!$A:$A, "Yes", 'בקרות להפחתת סיכון GCP (EN)'!$E:$E, I1), IF( AND($D$2=$O$3, $B$2=$N$3), COUNTIFS('בקרות להפחתת סיכון GCP (HEB)'!$A:$A, "Yes", 'בקרות להפחתת סיכון GCP (HEB)'!$E:$E, I1) ) ) ) ) -> 132 | J3: =IF( AND($D$2=$O$2, $B$2=$N$2), COUNTIFS('בקרות להפחתת סיכון AWS (EN)'!$A:$A, "Yes", 'בקרות להפחתת סיכון AWS (EN)'!$E:$E, J1), IF( AND($D$2=$O$3, $B$2=$N$2), COUNTIFS('בקרות להפחתת סיכון AWS (HEB)'!$A:$A, "Yes", 'בקרות להפחתת סיכון AWS (HEB)'!$E:$E, J1), IF( AND($D$2=$O$2, $B$2=$N$3), COUNTIFS('בקרות להפחתת סיכון GCP (EN)'!$A:$A, "Yes", 'בקרות להפחתת סיכון GCP (EN)'!$E:$E, J1), IF( AND($D$2=$O$3, $B$2=$N$3), COUNTIFS('בקרות להפחתת סיכון GCP (HEB)'!$A:$A, "Yes", 'בקרות להפחתת סיכון GCP (HEB)'!$E:$E, J1) ) ) ) ) -> 12 | K3: =IF( AND($D$2=$O$2, $B$2=$N$2), COUNTIFS('בקרות להפחתת סיכון AWS (EN)'!$A:$A, "Yes", 'בקרות להפחתת סיכון AWS (EN)'!$E:$E, K1), IF( AND($D$2=$O$3, $B$2=$N$2), COUNTIFS('בקרות להפחתת סיכון AWS (HEB)'!$A:$A, "Yes", 'בקרות להפחתת סיכון AWS (HEB)'!$E:$E, K1), IF( AND($D$2=$O$2, $B$2=$N$3), COUNTIFS('בקרות להפחתת סיכון GCP (EN)'!$A:$A, "Yes", 'בקרות להפחתת סיכון GCP (EN)'!$E:$E, K1), IF( AND($D$2=$O$3, $B$2=$N$3), COUNTIFS('בקרות להפחתת סיכון GCP (HEB)'!$A:$A, "Yes", 'בקרות להפחתת סיכון GCP (HEB)'!$E:$E, K1) ) ) ) ) -> 7 | L3: Total | N3: GCP | O3: עברית - מקוצר | S3: =E2 -> 218 | T3: =E2 -> 218 | U3: =IF( AND($D$2=$O$2, $B$2=$N$2), COUNTIFS(#REF!,"מערכת",#REF!,"Yes"), IF( AND($D$2=$O$3, $B$2=$N$2), COUNTIFS(#REF!,"מערכת",#REF!,"Yes"), IF( AND($D$2=$O$2, $B$2=$N$3), COUNTIFS(#REF!,"מערכת",#REF!,"Yes"), IF( AND($D$2=$O$3, $B$2=$N$3), COUNTIFS(#REF!,"מערכת",#REF!,"Yes") ) ) ) ) -> #REF! | V3: מערכת
A4: PaaS | G4: =IF( AND($D$2=$O$2, $B$2=$N$2), COUNTIF('בקרות להפחתת סיכון AWS (EN)'!$E:$E,G1), IF( AND($D$2=$O$3, $B$2=$N$2), COUNTIF('בקרות להפחתת סיכון AWS (HEB)'!$E:$E, G1), IF( AND($D$2=$O$2, $B$2=$N$3), COUNTIF('בקרות להפחתת סיכון GCP (EN)'!$E:$E, G1), IF( AND($D$2=$O$3, $B$2=$N$3), COUNTIF('בקרות להפחתת סיכון GCP (HEB)'!$E:$E, G1) ) ) ) ) -> 21 | H4: =IF( AND($D$2=$O$2, $B$2=$N$2), COUNTIF('בקרות להפחתת סיכון AWS (EN)'!$E:$E,H1), IF( AND($D$2=$O$3, $B$2=$N$2), COUNTIF('בקרות להפחתת סיכון AWS (HEB)'!$E:$E, H1), IF( AND($D$2=$O$2, $B$2=$N$3), COUNTIF('בקרות להפחתת סיכון GCP (EN)'!$E:$E, H1), IF( AND($D$2=$O$3, $B$2=$N$3), COUNTIF('בקרות להפחתת סיכון GCP (HEB)'!$E:$E, H1) ) ) ) ) -> 49 | I4: =IF( AND($D$2=$O$2, $B$2=$N$2), COUNTIF('בקרות להפחתת סיכון AWS (EN)'!$E:$E,I1), IF( AND($D$2=$O$3, $B$2=$N$2), COUNTIF('בקרות להפחתת סיכון AWS (HEB)'!$E:$E, I1), IF( AND($D$2=$O$2, $B$2=$N$3), COUNTIF('בקרות להפחתת סיכון GCP (EN)'!$E:$E, I1), IF( AND($D$2=$O$3, $B$2=$N$3), COUNTIF('בקרות להפחתת סיכון GCP (HEB)'!$E:$E, I1) ) ) ) ) -> 139 | J4: =IF( AND($D$2=$O$2, $B$2=$N$2), COUNTIF('בקרות להפחתת סיכון AWS (EN)'!$E:$E,J1), IF( AND($D$2=$O$3, $B$2=$N$2), COUNTIF('בקרות להפחתת סיכון AWS (HEB)'!$E:$E, J1), IF( AND($D$2=$O$2, $B$2=$N$3), COUNTIF('בקרות להפחתת סיכון GCP (EN)'!$E:$E, J1), IF( AND($D$2=$O$3, $B$2=$N$3), COUNTIF('בקרות להפחתת סיכון GCP (HEB)'!$E:$E, J1) ) ) ) ) -> 12 | K4: =IF( AND($D$2=$O$2, $B$2=$N$2), COUNTIF('בקרות להפחתת סיכון AWS (EN)'!$E:$E,K1), IF( AND($D$2=$O$3, $B$2=$N$2), COUNTIF('בקרות להפחתת סיכון AWS (HEB)'!$E:$E, K1), IF( AND($D$2=$O$2, $B$2=$N$3), COUNTIF('בקרות להפחתת סיכון GCP (EN)'!$E:$E, K1), IF( AND($D$2=$O$3, $B$2=$N$3), COUNTIF('בקרות להפחתת סיכון GCP (HEB)'!$E:$E, K1) ) ) ) ) -> 7 | L4: Part | N4: אחר | O4: English - Full | S4: =S3-S2 -> 113 | T4: =T3-T2 -> 193 | U4: =E2 -> 218
A5: SaaS | G5: =G4-G3 -> 1 | H5: =H4-H3 -> 2 | I5: =I4-I3 -> 7 | J5: =J4-J3 -> 0 | K5: =K4-K3 -> 0 | L5: Didn’t | O5: עברית - מלא | S5: =S2/S3 -> 0.48165138 | T5: =T2/T3 -> 0.1146789 | U5: =U2/U4 -> 0.56880734
G6: =G3/G4 -> 0.95238095 | H6: =H3/H4 -> 0.95918367 | I6: =I3/I4 -> 0.94964029 | J6: =J3/J4 -> 1 | K6: =K3/K4 -> 1 | S6: =S4/S3 -> 0.51834862 | T6: =T4/T3 -> 0.8853211 | U6: =U3/U4 -> #REF!
G7: =G5/G4 -> 0.047619048 | H7: =H5/H4 -> 0.040816327 | I7: =I5/I4 -> 0.050359712 | J7: =J5/J4 -> 0 | K7: =K5/K4 -> 0 | S7: =S2 & "/" &S3 -> 105/218 | T7: =T2 & "/" &T3 -> 25/218 | U7: =U2 & "/" &U4 -> 124/218
S16: כמות בקרות C | T16: כמות בקרות I | U16: כמות בקרות A
R17: מופעל | S17: =IF( AND($D$2=$O$2, $B$2=$N$2), COUNTIFS('בקרות להפחתת סיכון AWS (EN)'!$A:$A, "Yes", 'בקרות להפחתת סיכון AWS (EN)'!$X:$X, "x"), IF( AND($D$2=$O$3, $B$2=$N$2), COUNTIFS('בקרות להפחתת סיכון AWS (HEB)'!$A:$A, "Yes", 'בקרות להפחתת סיכון AWS (HEB)'!$X:$X, "x"), IF( AND($D$2=$O$2, $B$2=$N$3), COUNTIFS('בקרות להפחתת סיכון GCP (EN)'!$A:$A, "Yes", 'בקרות להפחתת סיכון GCP (EN)'!$X:$X, "x"), IF( AND($D$2=$O$3, $B$2=$N$3), COUNTIFS('בקרות להפחתת סיכון GCP (HEB)'!$A:$A, "Yes", 'בקרות להפחתת סיכון GCP (HEB)'!$X:$X, "x") ) ) ) ) -> 213 | T17: =IF( AND($D$2=$O$2, $B$2=$N$2), COUNTIFS('בקרות להפחתת סיכון AWS (EN)'!$A:$A, "Yes", 'בקרות להפחתת סיכון AWS (EN)'!$Y:$Y, "x"), IF( AND($D$2=$O$3, $B$2=$N$2), COUNTIFS('בקרות להפחתת סיכון AWS (HEB)'!$A:$A, "Yes", 'בקרות להפחתת סיכון AWS (HEB)'!$Y:$Y, "x"), IF( AND($D$2=$O$2, $B$2=$N$3), COUNTIFS('בקרות להפחתת סיכון GCP (EN)'!$A:$A, "Yes", 'בקרות להפחתת סיכון GCP (EN)'!$Y:$Y, "x"), IF( AND($D$2=$O$3, $B$2=$N$3), COUNTIFS('בקרות להפחתת סיכון GCP (HEB)'!$A:$A, "Yes", 'בקרות להפחתת סיכון GCP (HEB)'!$Y:$Y, "x") ) ) ) ) -> 147 | U17: =IF( AND($D$2=$O$2, $B$2=$N$2), COUNTIFS('בקרות להפחתת סיכון AWS (EN)'!$A:$A, "Yes", 'בקרות להפחתת סיכון AWS (EN)'!$Z:$Z, "x"), IF( AND($D$2=$O$3, $B$2=$N$2), COUNTIFS('בקרות להפחתת סיכון AWS (HEB)'!$A:$A, "Yes", 'בקרות להפחתת סיכון AWS (HEB)'!$Z:$Z, "x"), IF( AND($D$2=$O$2, $B$2=$N$3), COUNTIFS('בקרות להפחתת סיכון GCP (EN)'!$A:$A, "Yes", 'בקרות להפחתת סיכון GCP (EN)'!$Z:$Z, "x"), IF( AND($D$2=$O$3, $B$2=$N$3), COUNTIFS('בקרות להפחתת סיכון GCP (HEB)'!$A:$A, "Yes", 'בקרות להפחתת סיכון GCP (HEB)'!$Z:$Z, "x") ) ) ) ) -> 128
R18: סה"כ | S18: =IF( $C$2 = $A$2, IF( AND($D$2 = $O$2, $B$2 = $N$2), COUNTIFS('בקרות להפחתת סיכון AWS (EN)'!X:X, "x"), IF( AND($D$2 = $O$3, $B$2 = $N$2), COUNTIFS('בקרות להפחתת סיכון AWS (HEB)'!X:X, "x"), IF( AND($D$2 = $O$2, $B$2 = $N$3), COUNTIFS('בקרות להפחתת סיכון GCP (EN)'!X:X, "x"), IF( AND($D$2 = $O$3, $B$2 = $N$3), COUNTIFS('בקרות להפחתת סיכון GCP (HEB)'!X:X, "x"), "nnn" ) ) ) ), IF( $C$2 = $A$3, IF( AND($D$2 = $O$2, $B$2 = $N$2), COUNTIFS('בקרות להפחתת סיכון AWS (EN)'!X:X, "x", 'בקרות להפחתת סיכון AWS (EN)'!$K:$K, "x"), IF( AND($D$2 = $O$3, $B$2 = $N$2), COUNTIFS('בקרות להפחתת סיכון AWS (HEB)'!X:X, "x", 'בקרות להפחתת סיכון AWS (HEB)'!$K:$K, "x"), IF( AND($D$2 = $O$2, $B$2 = $N$3), COUNTIFS('בקרות להפחתת סיכון GCP (EN)'!X:X, "x", 'בקרות להפחתת סיכון GCP (EN)'!$K:$K, "x"), IF( AND($D$2 = $O$3, $B$2 = $N$3), COUNTIFS('בקרות להפחתת סיכון GCP (HEB)'!X:X, "x", 'בקרות להפחתת סיכון GCP (HEB)'!$K:$K, "x"), "nnn" ) ) ) ), IF( $C$2 = $A$4, IF( AND($D$2 = $O$2, $B$2 = $N$2), COUNTIFS('בקרות להפחתת סיכון AWS (EN)'!X:X, "x", 'בקרות להפחתת סיכון AWS (EN)'!$L:$L, "x"), IF( AND($D$2 = $O$3, $B$2 = $N$2), COUNTIFS('בקרות להפחתת סיכון AWS (HEB)'!X:X, "x", 'בקרות להפחתת סיכון AWS (HEB)'!$L:$L, "x"), IF( AND($D$2 = $O$2, $B$2 = $N$3), COUNTIFS('בקרות להפחתת סיכון GCP (EN)'!X:X, "x", 'בקרות להפחתת סיכון GCP (EN)'!$L:$L, "x"), IF( AND($D$2 = $O$3, $B$2 = $N$3), COUNTIFS('בקרות להפחתת סיכון GCP (HEB)'!X:X, "x", 'בקרות להפחתת סיכון GCP (HEB)'!$L:$L, "x"), "nnn" ) ) ) ), IF( $C$2 = $A$5, IF( AND($D$2 = $O$2, $B$2 = $N$2), COUNTIFS('בקרות להפחתת סיכון AWS (EN)'!X:X, "x", 'בקרות להפחתת סיכון AWS (EN)'!$M:$M, "x"), IF( AND($D$2 = $O$3, $B$2 = $N$2), COUNTIFS('בקרות להפחתת סיכון AWS (HEB)'!X:X, "x", 'בקרות להפחתת סיכון AWS (HEB)'!$M:$M, "x"), IF( AND($D$2 = $O$2, $B$2 = $N$3), COUNTIFS('בקרות להפחתת סיכון GCP (EN)'!X:X, "x", 'בקרות להפחתת סיכון GCP (EN)'!$M:$M, "x"), IF( AND($D$2 = $O$3, $B$2 = $N$3), COUNTIFS('בקרות להפחתת סיכון GCP (HEB)'!X:X, "x", 'בקרות להפחתת סיכון GCP (HEB)'!$M:$M, "x"), "nnn" ) ) ) ), "nnn" ) ) ) ) -> 221 | T18: =IF( $C$2 = $A$2, IF( AND($D$2 = $O$2, $B$2 = $N$2), COUNTIFS('בקרות להפחתת סיכון AWS (EN)'!Y:Y, "x"), IF( AND($D$2 = $O$3, $B$2 = $N$2), COUNTIFS('בקרות להפחתת סיכון AWS (HEB)'!Y:Y, "x"), IF( AND($D$2 = $O$2, $B$2 = $N$3), COUNTIFS('בקרות להפחתת סיכון GCP (EN)'!Y:Y, "x"), IF( AND($D$2 = $O$3, $B$2 = $N$3), COUNTIFS('בקרות להפחתת סיכון GCP (HEB)'!Y:Y, "x"), "nnn" ) ) ) ), IF( $C$2 = $A$3, IF( AND($D$2 = $O$2, $B$2 = $N$2), COUNTIFS('בקרות להפחתת סיכון AWS (EN)'!Y:Y, "x", 'בקרות להפחתת סיכון AWS (EN)'!$K:$K, "x"), IF( AND($D$2 = $O$3, $B$2 = $N$2), COUNTIFS('בקרות להפחתת סיכון AWS (HEB)'!Y:Y, "x", 'בקרות להפחתת סיכון AWS (HEB)'!$K:$K, "x"), IF( AND($D$2 = $O$2, $B$2 = $N$3), COUNTIFS('בקרות להפחתת סיכון GCP (EN)'!Y:Y, "x", 'בקרות להפחתת סיכון GCP (EN)'!$K:$K, "x"), IF( AND($D$2 = $O$3, $B$2 = $N$3), COUNTIFS('בקרות להפחתת סיכון GCP (HEB)'!Y:Y, "x", 'בקרות להפחתת סיכון GCP (HEB)'!$K:$K, "x"), "nnn" ) ) ) ), IF( $C$2 = $A$4, IF( AND($D$2 = $O$2, $B$2 = $N$2), COUNTIFS('בקרות להפחתת סיכון AWS (EN)'!Y:Y, "x", 'בקרות להפחתת סיכון AWS (EN)'!$L:$L, "x"), IF( AND($D$2 = $O$3, $B$2 = $N$2), COUNTIFS('בקרות להפחתת סיכון AWS (HEB)'!Y:Y, "x", 'בקרות להפחתת סיכון AWS (HEB)'!$L:$L, "x"), IF( AND($D$2 = $O$2, $B$2 = $N$3), COUNTIFS('בקרות להפחתת סיכון GCP (EN)'!Y:Y, "x", 'בקרות להפחתת סיכון GCP (EN)'!$L:$L, "x"), IF( AND($D$2 = $O$3, $B$2 = $N$3), COUNTIFS('בקרות להפחתת סיכון GCP (HEB)'!Y:Y, "x", 'בקרות להפחתת סיכון GCP (HEB)'!$L:$L, "x"), "nnn" ) ) ) ), IF( $C$2 = $A$5, IF( AND($D$2 = $O$2, $B$2 = $N$2), COUNTIFS('בקרות להפחתת סיכון AWS (EN)'!Y:Y, "x", 'בקרות להפחתת סיכון AWS (EN)'!$M:$M, "x"), IF( AND($D$2 = $O$3, $B$2 = $N$2), COUNTIFS('בקרות להפחתת סיכון AWS (HEB)'!Y:Y, "x", 'בקרות להפחתת סיכון AWS (HEB)'!$M:$M, "x"), IF( AND($D$2 = $O$2, $B$2 = $N$3), COUNTIFS('בקרות להפחתת סיכון GCP (EN)'!Y:Y, "x", 'בקרות להפחתת סיכון GCP (EN)'!$M:$M, "x"), IF( AND($D$2 = $O$3, $B$2 = $N$3), COUNTIFS('בקרות להפחתת סיכון GCP (HEB)'!Y:Y, "x", 'בקרות להפחתת סיכון GCP (HEB)'!$M:$M, "x"), "nnn" ) ) ) ), "nnn" ) ) ) ) -> 155 | U18: =IF( $C$2 = $A$2, IF( AND($D$2 = $O$2, $B$2 = $N$2), COUNTIFS('בקרות להפחתת סיכון AWS (EN)'!Z:Z, "x"), IF( AND($D$2 = $O$3, $B$2 = $N$2), COUNTIFS('בקרות להפחתת סיכון AWS (HEB)'!Z:Z, "x"), IF( AND($D$2 = $O$2, $B$2 = $N$3), COUNTIFS('בקרות להפחתת סיכון GCP (EN)'!Z:Z, "x"), IF( AND($D$2 = $O$3, $B$2 = $N$3), COUNTIFS('בקרות להפחתת סיכון GCP (HEB)'!Z:Z, "x"), "nnn" ) ) ) ), IF( $C$2 = $A$3, IF( AND($D$2 = $O$2, $B$2 = $N$2), COUNTIFS('בקרות להפחתת סיכון AWS (EN)'!Z:Z, "x", 'בקרות להפחתת סיכון AWS (EN)'!$K:$K, "x"), IF( AND($D$2 = $O$3, $B$2 = $N$2), COUNTIFS('בקרות להפחתת סיכון AWS (HEB)'!Z:Z, "x", 'בקרות להפחתת סיכון AWS (HEB)'!$K:$K, "x"), IF( AND($D$2 = $O$2, $B$2 = $N$3), COUNTIFS('בקרות להפחתת סיכון GCP (EN)'!Z:Z, "x", 'בקרות להפחתת סיכון GCP (EN)'!$K:$K, "x"), IF( AND($D$2 = $O$3, $B$2 = $N$3), COUNTIFS('בקרות להפחתת סיכון GCP (HEB)'!Z:Z, "x", 'בקרות להפחתת סיכון GCP (HEB)'!$K:$K, "x"), "nnn" ) ) ) ), IF( $C$2 = $A$4, IF( AND($D$2 = $O$2, $B$2 = $N$2), COUNTIFS('בקרות להפחתת סיכון AWS (EN)'!Z:Z, "x", 'בקרות להפחתת סיכון AWS (EN)'!$L:$L, "x"), IF( AND($D$2 = $O$3, $B$2 = $N$2), COUNTIFS('בקרות להפחתת סיכון AWS (HEB)'!Z:Z, "x", 'בקרות להפחתת סיכון AWS (HEB)'!$L:$L, "x"), IF( AND($D$2 = $O$2, $B$2 = $N$3), COUNTIFS('בקרות להפחתת סיכון GCP (EN)'!Z:Z, "x", 'בקרות להפחתת סיכון GCP (EN)'!$L:$L, "x"), IF( AND($D$2 = $O$3, $B$2 = $N$3), COUNTIFS('בקרות להפחתת סיכון GCP (HEB)'!Z:Z, "x", 'בקרות להפחתת סיכון GCP (HEB)'!$L:$L, "x"), "nnn" ) ) ) ), IF( $C$2 = $A$5, IF( AND($D$2 = $O$2, $B$2 = $N$2), COUNTIFS('בקרות להפחתת סיכון AWS (EN)'!Z:Z, "x", 'בקרות להפחתת סיכון AWS (EN)'!$M:$M, "x"), IF( AND($D$2 = $O$3, $B$2 = $N$2), COUNTIFS('בקרות להפחתת סיכון AWS (HEB)'!Z:Z, "x", 'בקרות להפחתת סיכון AWS (HEB)'!$M:$M, "x"), IF( AND($D$2 = $O$2, $B$2 = $N$3), COUNTIFS('בקרות להפחתת סיכון GCP (EN)'!Z:Z, "x", 'בקרות להפחתת סיכון GCP (EN)'!$M:$M, "x"), IF( AND($D$2 = $O$3, $B$2 = $N$3), COUNTIFS('בקרות להפחתת סיכון GCP (HEB)'!Z:Z, "x", 'בקרות להפחתת סיכון GCP (HEB)'!$M:$M, "x"), "nnn" ) ) ) ), "nnn" ) ) ) ) -> 128
R19: לא מופעל | S19: =S18-S17 -> 8 | T19: =T18-T17 -> 8 | U19: =U18-U17 -> 0
S20: =S17/S18 -> 0.9638009 | T20: =T17/T18 -> 0.9483871 | U20: =U17/U18 -> 1
A22: אזהרה!!! | S22: 54 | T22: 46 | U22: 51 | V22: הכי נמוך
A23: שינוי מילים או מיקומי שדות ועדכון נוסחאות ישפיעו על תוצאות המחשבון
A24: נבנה על ידי אבא אקילוב

Sheet חישוב תמק
A1: דומיין | B1: ציון | C1: ציון מקסימלי | D1: אחוז אי העמידה בתקן | E1: משקל | H1: M4 | I1: M3 | J1: M2 | K1: M1 | L1: upper | M1: lower | N1: blank | O1: סיכון | P1: דומיין
A2: כשירות ארגונית | B2: =SUM('כשירות ארגונית (1)'!F5:F21) -> 8 | C2: =SUM('כשירות ארגונית (1)'!G5:G21) -> 23 | D2: =E13 -> 0.48205128 | E2: 1 | H2: 0.02 | I2: 0.05 | J2: 0.02 | K2: 0.05 | L2: 0.15 | M2: 0.2 | N2: =1-O2 -> 0.25 | O2: =_xlfn.NUMBERVALUE(E5) -> 0.75 | P2: סף רגישות כולל
A3: פרופיל מערכת | B3: =SUM('פרופיל מערכת (2)'!F5:F52) -> 140 | C3: =SUM('פרופיל מערכת (2)'!G5:G52) -> 241 | D3: =E21 -> 0.69792904 | E3: 10 | H3: 0.02 | I3: 0.05 | J3: 0.02 | K3: 0.05 | L3: 0.15 | M3: 0.2 | N3: =1-O3 -> 0.51794872 | O3: =D2 -> 0.48205128 | P3: כשירות ארגונית
A4: שרשרת אספקה | B4: =SUM('שרשרת אספקה (3)'!F5:F37) -> 37 | C4: =SUM('שרשרת אספקה (3)'!G5:G37) -> 103 | D4: =E27 -> 0.36519194 | E4: 1 | H4: 0.02 | I4: 0.05 | J4: 0.02 | K4: 0.05 | L4: 0.15 | M4: 0.2 | N4: =1-O4 -> 0.30207096 | O4: =D3 -> 0.69792904 | P4: פרופיל מערכת
E5: =IF(ISBLANK('כללי (0)'!C13),"75%",IF(OR('סיווג אופי מידע במערכת (4)'!D6="שמור אדום",'סיווג אופי מידע במערכת (4)'!D6="סודי"),"100%",SUMPRODUCT(D2:D4,E2:E4)/SUM(E2:E4))) -> 75% | F5: סה"כ | H5: 0.02 | I5: 0.05 | J5: 0.02 | K5: 0.05 | L5: 0.15 | M5: 0.2 | N5: =1-O5 -> 0.63480806 | O5: =D4 -> 0.36519194 | P5: שרשרת אספקה
E6: 1
A7: כשירות ארגונית | B7: ציון | C7: ציון מקסימלי | D7: אחוז אי העמידה בתקן | E7: משקל | K7: =IF(OR(O2>=70%,O3>=70%,O4>=70%,O5>=70%),"על סמך ניתוח המערכת הנך נדרש לפנות למנחה לבחינת ההיתכנות להעלאת המערכת לענן","על סמך ניתוח המערכת הנך נדרש לעדכן את המחנה בתוצאות הבחינה ולהמשיך בתהליך במודל רגולציה עצמית") -> על סמך ניתוח המערכת הנך נדרש לפנות למנחה לבחינת ההיתכנות להעלאת המערכת לענן
A8: אסטרטגיה | B8: =SUM('כשירות ארגונית (1)'!F5:F6) -> 1 | C8: =SUM('כשירות ארגונית (1)'!G5:G6) -> 3 | D8: =B8/C8 -> 0.33333333 | E8: 1
A9: ניהול סיכונים | B9: =SUM('כשירות ארגונית (1)'!F9:F10) -> 1 | C9: =SUM('כשירות ארגונית (1)'!G9:G10) -> 13 | D9: =B9/C9 -> 0.076923077 | E9: 1
A10: משאבי כ"א בתחום הענן | B10: =SUM('כשירות ארגונית (1)'!F13:F13) -> 1 | C10: =SUM('כשירות ארגונית (1)'!G13:G13) -> 1 | D10: =B10/C10 -> 1 | E10: 1
A11: ניהול פיננסי | B11: =SUM('כשירות ארגונית (1)'!F16:F17) -> 5 | C11: =SUM('כשירות ארגונית (1)'!G16:G17) -> 5 | D11: =B11/C11 -> 1 | E11: 1
A12: מדיניות, שיטות, נהלים ותהליכים | B12: =SUM('כשירות ארגונית (1)'!F20:F20) -> 0 | C12: =SUM('כשירות ארגונית (1)'!G20:G20) -> 1 | D12: =B12/C12 -> 0 | E12: 1
E13: =SUMPRODUCT(D8:D12,E8:E12)/SUM(E8:E12) -> 0.48205128 | F13: סה"כ
A15: פרופיל מערכת | B15: ציון | C15: ציון מקסימלי | D15: אחוז אי העמידה בתקן | E15: משקל
A16: מאפייני מידע | B16: =SUM('פרופיל מערכת (2)'!F5:F12) -> 28 | C16: =SUM('פרופיל מערכת (2)'!G5:G12) -> 45 | D16: =B16/C16 -> 0.62222222 | E16: 1
A17: מאפייני מערכת | B17: =SUM('פרופיל מערכת (2)'!F15:F23) -> 102 | C17: =SUM('פרופיל מערכת (2)'!G15:G23) -> 131 | D17: =B17/C17 -> 0.77862595 | E17: 20
A18: משתמשים והזדהות | B18: =SUM('פרופיל מערכת (2)'!F26:F34) -> 6 | C18: =SUM('פרופיל מערכת (2)'!G26:G34) -> 27 | D18: =B18/C18 -> 0.22222222 | E18: 1
A19: ממשקים | B19: =SUM('פרופיל מערכת (2)'!F37:F43) -> 0 | C19: =SUM('פרופיל מערכת (2)'!G37:G43) -> 26 | D19: =B19/C19 -> 0 | E19: 1
A20: אופן היישום בענן | B20: =SUM('פרופיל מערכת (2)'!F46:F52) -> 4 | C20: =SUM('פרופיל מערכת (2)'!G46:G52) -> 12 | D20: =B20/C20 -> 0.33333333 | E20: 1
E21: =SUMPRODUCT(D16:D20,E16:E20)/SUM(E16:E20) -> 0.69792904 | F21: סה"כ
A23: שרשרת אספקה | B23: ציון | C23: ציון מקסימלי | D23: אחוז אי העמידה בתקן | E23: משקל
A24: מאפייני הספקים | B24: =SUM('שרשרת אספקה (3)'!F5:F11) -> 2 | C24: =SUM('שרשרת אספקה (3)'!G5:G11) -> 9 | D24: =B24/C24 -> 0.22222222 | E24: 1
A25: ספק א' | B25: =SUM('שרשרת אספקה (3)'!F15:F24) -> 20 | C25: =SUM('שרשרת אספקה (3)'!G15:G24) -> 47 | D25: =B25/C25 -> 0.42553191 | E25: 10
A26: ספק ב' | B26: =SUM('שרשרת אספקה (3)'!F28:F37) -> 15 | C26: =SUM('שרשרת אספקה (3)'!G28:G37) -> 47 | D26: =B26/C26 -> 0.31914894 | E26: 10
E27: =SUMPRODUCT(D24:D26,E24:E26)/SUM(E24:E26) -> 0.36519194 | F27: סה"כ

Sheet שרשרת אספקה (3)
C3: מאפייני הספקים
D4: תשובה | F4: ציון | G4: ציון מקסימלי | H4: תשובה 1 | I4: תשובה 2 | J4: תשובה 3 | K4: תשובה 4
B5: מאפייני הספקים | C5: האם הארגון משתמש באינטגרטור מוסמך על ידי הספק להקמת המערכת? | D5: כן | F5: =IF(D5=H5,0,IF(D5=I5,1,"ERROR")) -> 0 | G5: 1 | H5: כן | I5: לא
C6: האם הספקים רשומים במאגר הספקים וחברות שרשרת האספקה "מערכת יובל" | D6: כן | F6: =IF(D6=H6,0,IF(D6=I6,1,"ERROR")) -> 0 | G6: 1 | H6: כן | I6: לא
C7: האם קיים אינטגרטור אשר מנהל בפועל את השימוש הענן? | D7: לא | F7: =IF(D7=H7,0,IF(D7=I7,1,"ERROR")) -> 0 | G7: 1 | H7: לא | I7: כן
C8: האם יש לספקים ביטוח סייבר אשר כולל בין היתר שיפוי לנזקים עבור צד ג' | D8: לא | F8: =IF(D8=H8,0,IF(D8=I8,1,"ERROR")) -> 1 | G8: 1 | H8: כן | I8: לא
C9: האם הספקים עברו תהליכי בדיקות מהימנות לספק ולעובדים בפרויקט? | D9: כן | F9: =IF(D9=H9,0,IF(D9=I9,1,"ERROR")) -> 0 | G9: 1 | H9: כן | I9: לא
C10: האם הספקים עומדים בהסמכות ISO 27K | D10: לא | F10: =IF(D10=H10,0,IF(D10=I10,1,"ERROR")) -> 1 | G10: 1 | H10: כן | I10: לא
C11: מספר הספקים בפרויקט | D11: ספק אחד | F11: =IF(D11=H11,0,IF(D11=I11,1,IF(D11=J11,2,IF(D11=K11,3,"ERROR")))) -> 0 | G11: 3 | H11: ספק אחד | I11: שני ספקים | J11: שלושה ספקים | K11: 4 ומעלה
B13: ספק א' | D13: תשובה
B14: ספק א' | C14: שם הספק
C15: האם מוגדר כספק מהותי | D15: לא | F15: =IF(D15=H15,0,IF(D15=I15,1,"ERROR")) -> 1 | G15: 1 | H15: כן | I15: לא
C16: האם הספק רשום במאגר הספקים וחברות שרשרת האספקה "מערכת יובל" | D16: כן | F16: =IF(D16=H16,0,IF(D16=I16,1,"ERROR")) -> 0 | G16: 1 | H16: כן | I16: לא
C17: תפקיד הספק | D17: אינטגרציה | F17: =IF(D17=H17,0,IF(D17=I17,1,IF(D17=J17,2,IF(D17=K17,3,"ERROR")))) -> 3 | G17: 3 | H17: ייעוץ | I17: פיתוח | J17: הקמה | K17: אינטגרציה
C18: תלות בספק | D18: תלות נמוכה | F18: =IF(D18=H18,0,IF(D18=I18,1,IF(D18=J18,2,IF(D18=K18,3,"ERROR")))) -> 1 | G18: 3 | H18: ללא תלות | I18: תלות נמוכה | J18: תלות בינונית | K18: תלות גבוהה
C19: רמת הנזק הצפוי לאגון מהספק | D19: בינוני | F19: =IF(D19=H19,0,IF(D19=I19,1,IF(D19=J19,5,IF(D19=K19,10,"ERROR")))) -> 5 | G19: 10 | H19: ללא נזק | I19: נמוך | J19: בינוני | K19: גבוהה
C20: נזק כלכלי לארגון כתוצאה מפגיעה בספק | D20: עשרות אלפי שקלים | F20: =IF(D20=H20,0,IF(D20=I20,1,IF(D20=J20,2,IF(D20=K20,3,"ERROR")))) -> 1 | G20: 3 | H20: ללא נזק | I20: עשרות אלפי שקלים | J20: מאות אלפי שקלים | K20: מעל מליון
C21: מידת הפגיעה ברציפות העסקית מפגיעה בספק | D21: התאוששות מאירוע אצל הספק תיקח מספר ימים | F21: =IF(D21=H21,0,IF(D21=I21,1,IF(D21=J21,5,IF(D21=K21,10,"ERROR")))) -> 5 | G21: 10 | H21: ללא נזק | I21: התאוששות מאירוע אצל הספק תיקח מספר שעות | J21: התאוששות מאירוע אצל הספק תיקח מספר ימים | K21: התאוששות מאירוע אצל הספק תיקח מספר שבועות
C22: רמת רגישות המידע הנגיש לספק | D22: מידע בעל רגישות נמוכה | F22: =IF(D22=H22,0,IF(D22=I22,1,IF(D22=J22,2,IF(D22=K22,3,"ERROR")))) -> 1 | G22: 3 | H22: ללא מידע | I22: מידע בעל רגישות נמוכה | J22: מידע בעל רגישות בינונית | K22: מידע בעל רגישות עסקית כגון פטנטים וסודות מסחריים
C23: סבירות להתממשות אירוע כתוצאה מההתקשרות | D23: תלות נמוכה בסייבר | F23: =IF(D23=H23,0,IF(D23=I23,1,IF(D23=J23,5,IF(D23=K23,10,"ERROR")))) -> 1 | G23: 10 | H23: ללא תלות | I23: תלות נמוכה בסייבר | J23: תלות בינונית בסייבר בהתקשרות עם הספק | K23: ספק בעל תלות גבוהה בסייבר
C24: האם הוגדר SLA עם הספק לטיפול בפערי אבטחת מידע | D24: הוגדר טיפול של עד 30 יום | F24: =IF(D24=H24,0,IF(D24=I24,1,IF(D24=J24,2,IF(D24=K24,3,"ERROR")))) -> 2 | G24: 3 | H24: טיפול מיידי | I24: הוגדר טיפול תוך תוך שעות עד ימים בודדים | J24: הוגדר טיפול של עד 30 יום | K24: הוגדר Best Effort
B26: ספק ב' | D26: תשובה
B27: ספק ב' | C27: שם הספק
C28: האם מוגדר כספק מהותי | D28: לא | F28: =IF(D28=H28,0,IF(D28=I28,1,"ERROR")) -> 1 | G28: 1 | H28: כן | I28: לא
C29: האם הספק רשום במאגר הספקים וחברות שרשרת האספקה "מערכת יובל" | D29: לא | F29: =IF(D29=H29,0,IF(D29=I29,1,"ERROR")) -> 1 | G29: 1 | H29: כן | I29: לא
C30: תפקיד הספק | D30: פיתוח | F30: =IF(D30=H30,0,IF(D30=I30,1,IF(D30=J30,2,IF(D30=K30,3,"ERROR")))) -> 1 | G30: 3 | H30: ייעוץ | I30: פיתוח | J30: הקמה | K30: אינטגרציה
C31: תלות בספק | D31: תלות נמוכה | F31: =IF(D31=H31,0,IF(D31=I31,1,IF(D31=J31,2,IF(D31=K31,3,"ERROR")))) -> 1 | G31: 3 | H31: ללא תלות | I31: תלות נמוכה | J31: תלות בינונית | K31: תלות גבוהה
C32: רמת הנזק הצפוי לאגון מהספק | D32: נמוך | F32: =IF(D32=H32,0,IF(D32=I32,1,IF(D32=J32,5,IF(D32=K32,10,"ERROR")))) -> 1 | G32: 10 | H32: ללא נזק | I32: נמוך | J32: בינוני | K32: גבוהה
C33: נזק כלכלי לארגון כתוצאה מפגיעה בספק | D33: מאות אלפי שקלים | F33: =IF(D33=H33,0,IF(D33=I33,1,IF(D33=J33,2,IF(D33=K33,3,"ERROR")))) -> 2 | G33: 3 | H33: ללא נזק | I33: עשרות אלפי שקלים | J33: מאות אלפי שקלים | K33: מעל מליון
C34: מידת הפגיעה ברציפות העסקית מפגיעה בספק | D34: ללא נזק | F34: =IF(D34=H34,0,IF(D34=I34,1,IF(D34=J34,5,IF(D34=K34,10,"ERROR")))) -> 0 | G34: 10 | H34: ללא נזק | I34: התאוששות מאירוע אצל הספק תיקח מספר שעות | J34: התאוששות מאירוע אצל הספק תיקח מספר ימים | K34: התאוששות מאירוע אצל הספק תיקח מספר שבועות
C35: רמת רגישות המידע הנגיש לספק | D35: מידע בעל רגישות נמוכה | F35: =IF(D35=H35,0,IF(D35=I35,1,IF(D35=J35,2,IF(D35=K35,3,"ERROR")))) -> 1 | G35: 3 | H35: ללא מידע | I35: מידע בעל רגישות נמוכה | J35: מידע בעל רגישות בינונית | K35: מידע בעל רגישות עסקית כגון פטנטים וסודות מסחריים
C36: סבירות להתממשות אירוע כתוצאה מההתקשרות | D36: תלות בינונית בסייבר בהתקשרות עם הספק | F36: =IF(D36=H36,0,IF(D36=I36,1,IF(D36=J36,5,IF(D36=K36,10,"ERROR")))) -> 5 | G36: 10 | H36: ללא תלות | I36: תלות נמוכה בסייבר | J36: תלות בינונית בסייבר בהתקשרות עם הספק | K36: ספק בעל תלות גבוהה בסייבר
C37: האם הוגדר SLA עם הספק לטיפול בפערי אבטחת מידע | D37: הוגדר טיפול של עד 30 יום | F37: =IF(D37=H37,0,IF(D37=I37,1,IF(D37=J37,2,IF(D37=K37,3,"ERROR")))) -> 2 | G37: 3 | H37: טיפול מיידי | I37: הוגדר טיפול תוך תוך שעות עד ימים בודדים | J37: הוגדר טיפול של עד 30 יום | K37: הוגדר Best Effort

Sheet סיווג אופי מידע במערכת (4)
C5: הערכת סיווג ואופי המידע | D5: תשובה
A6: Q4.1 | B6: פומביות המידע | C6: סיווג המידע במערכת | D6: בלמס
A7: Q4.2 | C7: האם קיימת מניעה משפטית (חוק, תקנה או דרישה רגולטורית) להנגשת המידע לציבור? | D7: כן
A9: Q4.3 | B9: פרטיות המידע | C9: האם הנתונים מכילים מידע פרטי (כולל מזהים ישירים/עקיפים) כהגדרתו במסמך זה? | D9: כן
A10: Q4.4 | C10: האם הנתונים מכילים מידע פרטי בעל רגישות מיוחדת כהגדרתו במסמך זה? | D10: לא
A11: Q4.5 | C11: האם המידע נוגע לעניינים פנימיים של הגוף המונחה? | D11: לא
A13: Q4.6 | B13: השפעת חשיפה או פגיעה במידע/במערכת על התנהלות הגוף המונחה או הציבור | C13: חשיפת מידע אסטרטגי לישויות מדיניות זרות (מדינות, רשויות או ארגונים בינ"ל) | D13: לא
A14: Q4.7 | C14: השפעה על הציבור או המשק או פגיעה בהם, הטיה או מתן יתרון תחרותי בלתי הוגן. | D14: לא
A15: Q4.8 | C15: פוטנציאל לפגיעה בגוף או בנפש או פגיעה כלכלית בהתאם לתבחיני תמ"ק ? | D15: לא
A16: Q4.9 | C16: פוטנציאל פגיעה באופן רוחבי\ נרחב במספר גופים | D16: לא
C17: ↘ ↙
B18: תוצאת סיווג ואופי המידע
B19: ='חישובים ונתונים'!B12 -> בלמס - מידע פנימי
B21: הגדרות הסיווג הביטחוני
B22: סיווג המידע | C22: סיווג המידע | D22: רמה
B23: מידע בלמ"ס | C23: מידע, אשר אם יגיעו לידי גורם שאיננו מוסמך לכך, לא ייגרם נזק ביטחוני | D23: 1
B24: שמור צהוב | C24: מידע, אשר אם יגיעו לידי גורם שאיננו מוסמך לכך, עלול לסייע בפגוע בביטחון מדינת ישראל | D24: 2
B25: שמור אדום | C25: בהתאם להגדרות התו"ל | D25: 3
B26: סודי | C26: בהתאם להגדרות התו"ל | D26: 4
B28: הגדרות סיווג אופי המידע במערכת (בסיווג בלמ"ס)
B29: אופי המידע | C29: אופי המידע | D29: רמה
B30: מידע פומבי | C30: מידע שפורסם באופן חוקי לציבור או מידע המותר לפרסום לכלל הציבור על פי דין | D30: 1
B31: מידע פנימי | C31: מידע הנוגע לענייניה הפנימיים של הגוף המונחה, המיועד לשימוש פנימי בארגון או בין מספר משרדים, שאין לפרסמו לכלל הציבור ואינו מכיל מידע פרטי. | D31: 2
B32: מידע פנימי מוגבל | C32: מידע המיועד לשימוש פנימי בארגון אשר חלות עליו הגבלות על פי חוק (לדוגמה, סודיות מסחרית), תקנות (לדוגמה, תקנות חובת המכרזים) רגולציה ייעודית או הסכם או מידע פרטי שאינו מידע בעל רגישות מיוחדת. | D32: 3
B33: מידע פנימי חסוי | C33: מידע פרטי בעל רגישות מיוחדת או מידע שהחוק או התקנות או רגולציה או הארגון קבעו שהסיווג עבורו גבוה במיוחד. | D33: 4

Sheet הערכת נזק פוטנציאלי למערכת (5)
B4: הגדרות חומרת הנזק הפוטנציאלי למערכת ולמידע
B5: חומרת הנזק | C5: אופי הנזק הפוטנציאלי | J5: רמת הנזק
B6: נזק מינמלי | C6: מערכת ומידע שחשיפתם או פגיעה בהם תגרום נזק מינימלי | J6: 1
B7: נזק מוגבל | C7: מערכת ומידע שלחשיפתם או לפגיעה בהם עשויה להיות השפעה שלילית מוגבלת על תפקוד הארגון או תדמיתו | J7: 2
B8: נזק בינוני | C8: מערכת ומידע שחשיפתם או הפגיעה בהם תגרום להשפעה שלילית גבוהה לארגון או לממשלה | J8: 3
B9: נזק חמור | C9: מערכת ומידע שחשיפתם או הפגיעה בהם תגרום לנזק חמור במיוחד לציבור או לאינטרס הלאומי | J9: 4
B12: הערכת הנזק הפוטנציאלי בהיבטי חסיון, אמינות וזמינות המידע והמערכת
B13: ההערכה תתבצע ע"פ מקרא הגדרות הנזק הפוטנציאלי מטה
C14: פגיעה בתקציב הארגון | D14: נזק לתדמית הארגון בעיני הציבור | E14: פגיעה בייעדי רציפות התפקודית | F14: פגיעה בייעדי מתן שירות לציבור \ ללקוחות | G14: חשיפה משפטית/ רגולטורית / משילות | H14: נכס מידע תשתיתי רוחבי | I14: פגיעה בביטחון/ בטיחות/ שלום הציבור או עובדי הארגון | J14: סיכום מידת הנזק המקסימאלית
A15: Q3.1 | B15: חסיון (חשיפת המידע או המערכת) Confidentiality | C15: מינימלית | D15: מינימלי | E15: מוגבלת | F15: מוגבלת | G15: מינימלית | H15: מוגבלות | I15: מינימלית | J15: ='חישובים ונתונים'!S42 -> מוגבלת
A16: Q3.2 | B16: אמינות (שלמות המידע או מערכת) Integrity | C16: מינימלית | D16: מינימלי | E16: מוגבלת | F16: מינימלית | G16: מינימלית | H16: מוגבלות | I16: מינימלית | J16: ='חישובים ונתונים'!S43 -> מוגבלת
A17: Q3.3 | B17: זמינות (מידע או מערכת) Availability | C17: מינימלית | D17: מינימלי | E17: מינימלית | F17: מינימלית | G17: מינימלית | H17: מינימליות | I17: בינונית | J17: ='חישובים ונתונים'!S44 -> בינונית
B18: הערות (במידה ויש)
F19: ↘ ↙
B21: תוצאת הנזק הפוטנציאלי מפגיעה במערכת ובמידע
B22: ='חישובים ונתונים'!D39 -> מידת הנזק הפוטנציאלי הצפוי למשרד הוא - נזק בינוני
B25: מקרא הגדרות הנזק הפוטנציאלי
B26: קריטריון | C26: פגיעה כלכלית בארגון | D26: נזק לתדמית הארגון בעיני הציבור | E26: פגיעה בייעדי רציפות התפקודית | F26: פגיעה בייעדי מתן שירות לציבור \ ללקוחות | G26: חשיפה משפטית/ רגולטורית / משילות | H26: נכס מידע תשתיתי רוחבי | I26: פגיעה בביטחון/ בטיחות/ שלום הציבור או עובדי הארגון
B27: נזק מינימלי | C27: ללא פגיעה כלכלית בארגון | D27: ללא נזק תדמיתי או חשיפה תקשורתית נמוכה | E27: ללא פגיעה ברציפות התפקודית | F27: ללא פגיעה במתן שירות לציבור או הללקוחות / לא רלוונטי | G27: ללא חשיפה משפטית | H27: ללא השפעה | I27: ללא פגיעה
B28: נזק מוגבל | C28: פגיעה של עד 0.5% מהתקציב התפעולי השנתי של הארגון או המשרד הממשלתי | D28: כיסוי תקשורתי שלילי של כלי התקשורת איזוטריים | E28: פגיעה מצומצמת ברציפות התפקודית תוך עמידה ביעדים | F28: פגיעה נקודתית במתן שירות לציבור / ללקחות תוך עמידה ביעדים | G28: חשיפה נמוכה מאוד לתביעות משפטיות | H28: השפעה על נכס מידע תשתיתי לא אסטרטגי בודד | I28: פגיעה נקודתית
B29: נזק בינוני | C29: פגיעה מצומצמת עד 2% מהתקציב התפעולי השנתי של הארגון או המשרד הממשלתי | D29: כיסוי תקשורתי שלילי נרחב ברמה הלאומית בעל השלכות המצריכות תקשור לציבור | E29: פגיעה נמוכה ביעדי הרציפות התפקודית | F29: פגיעה נרחבת במתן שירותים לציבור / ללקוחות תוך עמידה ביעדים | G29: חשיפה נמוכה לתביעות משפטיות | H29: השפעה על מספר נכסים לא אסטרטגיים או על נכס אסטרטגי בודד | I29: פגיעה נרחבת בודדת או מספר פגיעות נקודתיות
B30: נזק חמור | C30: פגיעה משמעותית של מעל 2% מהתקציב התפעולי השנתי של הארגון או המשרד הממשלתי | D30: כיסוי תקשורתי שלילי משמעותי ברמה בינלאומית עד כדי עצירת פעילות הארגון (יתכן והאירוע מצריך מתן הסברים ובירורים על ידי גורמי רגולציה חיצוניים) | E30: פגיעה חמורה וממושכת ביעדי הרציפות התפקודית | F30: פגיעה נרחבת במתן שירותים לציבור / ללקוחות לתקופת זמן ממושכת וחריגה מייעדי השירות | G30: חשיפה משפטית לקובלנה פלילית, אפשרות לעצירת פעילות הארגון או המשרד הממשלתי | H30: השפעה על מספר נכסים אסטרטגיים עד כדי הפסקת פעילות הארגון או המשרד הממשלתי | I30: מספר פגיעות נרחבות

Sheet מערכות הגנה (6)
C4: מערכות הגנה | D4: תשובה | E4: שם המערכת
B5: הגנת רשת | C5: האם תוטמע מערכת חומת אש Firewall (כולל IDS\IPS) | D5: לא | E5: אין FW/IDS/IPS ייעודי — הגנת רשת ברובד ה-Edge של ספק הענן
C6: האם תוטמע מערכת חומת אש אפליקטיבית Web Application Firwall (WAF) | D6: כן | E6: Vercel Firewall / Attack Challenge Mode (אומת בפועל: x-vercel-mitigated: challenge)
C7: האם תוטמע מערכת אבטחת ממשקים (API Gateway) | D7: לא | E7: ממשקי API ממומשים כ-Route Handlers של Next.js עם אימות והרשאות בצד השרת
C8: האם תוטמע מערכת האצת תוכן (CDN) | D8: כן | E8: Vercel Edge Network (CDN)
C9: האם תוטמע מערכת אבטחת אינטרנט של דברים (IOT) | D9: לא | E9: אין רכיבי IoT במערכת
B11: אבטחת מידע | C11: האם תוטמע מערכת לזיהוי מידע רגיש (Discovery And Classification) | D11: לא | E11: -
C12: האם תוטמע מערכת למניעת איבוד מידע (DLP) | D12: לא | E12: -
C13: האם תוטמע מערכת אבטחת בסיסי נתונים | D13: כן | E13: Neon PostgreSQL — TLS בתעבורה, הצפנה במנוחה, בידוד רשת והרשאות
C14: האם תוטמע מערכת לשמירה על פרטיות מידע (Data Privecy) | D14: לא | E14: -
B17: פוגענים ונוזקות | C17: האם תוטמע מערכת לזיהוי ושיקום מתקדמת XDR | D17: לא | E17: -
C18: האם תוטמע מערכת הלבנת קבצים (CDR + Sandbox) | D18: לא | E18: פער מזוהה — נדרש CDR/Sandbox להעלאת קבצים (GIS / מפות מדידה) לפני ייצור
B20: הגנת סביבת ענן | C20: האם תוטמע מערכת אבטחת צופן ייעודית (HSM) | D20: לא | E20: -
C21: האם תוטמע מערכת ניהול בקרת תצורת אבטחת ענן (CSPM) | D21: לא | E21: -
C22: מערכת ניהול מפתחות וסודות (KMS) | D22: כן | E22: ניהול סודות במשתני סביבה של Vercel ומפתחות מנוהלים בענן (Neon)
C23: האם תוטמע מערכת הגנה על סביבת עבודה בענן (CWPP) | D23: לא | E23: -
B25: ניטור ותגובה | C25: האם תוטמע מערכת ניהול התראות אבטחה מרכזית (SIEM) | D25: לא | E25: פער מזוהה — נדרש חיבור לניטור SIEM/SOC ארגוני לפני ייצור
C26: האם תוטמע מערכת גילוי משטחת תקיפה חיצוני (EASM) | D26: לא | E26: -
C27: האם תוטמע מערכת ציד מודיעין עסקי (Threat Intelligence) | D27: לא | E27: -
C28: האם תוטמע מערכת תגובה לאירועים באופן אוטומטי (SOAR) | D28: לא | E28: -
B30: ניהול זהויות | C30: האם תוטמע מערכת ניהול זהויות מרכזית (IDP) | D30: לא | E30: כיום הזדהות מקומית ל-CMS (סיסמה בגיבוב SHA-256, עוגייה חתומה). מתוכנן: SSO ארגוני
C31: מערכת ניטור הרשאות ענן (CIEM) | D31: לא | E31: -
C32: האם תוטמע מערכת סוכן אבטחה של גישה לענן (CASB) | D32: לא | E32: -
B34: הגנת סביבות פיתוח | C34: האם תוטמע מערכת זיכוי קוד פיתוח בשלב הפיתוח ההטמעה CICD (בסגנון Snyk, jfrog) | D34: כן | E34: בדיקת אבטחה אוטומטית בצנרת: npm audit ו-npm run security:check (סריקת סודות וכותרות אבטחה)
C35: האם תוטמע מערכת ניהול חשיפות תוכנה (Automated patch management) | D35: כן | E35: עדכוני תלויות ו-npm audit, כולל overrides לחסימת גרסאות פגיעות
C36: האם תוטמע מערכת ניהול אבטחת קונטיינרים | D36: לא | E36: אין קונטיינרים — ארכיטקטורת Serverless

Sheet ארכיטקטורה מלאה (7)
B4: ארכיטקטורה
C5: תרשים זרימה תהליכי
C6: נא לצרף טופולוגית ענן + ON PREM (כולל ממשקים)
B22: תרשים זרימה תהליכי
C24: נא לצרף תרשים זרימה תהליכי

Sheet פרופיל בקרות דרוש (8)
D2: תצורת ענן מבוקשת | E2: ='פרופיל מערכת (2)'!D50 -> IaaS
D3: ספק הענן | E3: =IF('פרופיל מערכת (2)'!D49="AWS","AWS",IF('פרופיל מערכת (2)'!D49="GCP","GCP","AWS")) -> GCP
D4: תצוגה | E4: עברית - מקוצר
B9: {=IF( AND(E4=חישובים!O2, E3=חישובים!N2), IF( INDEX(AWS[], SMALL(IF((AWS[Column1]=חישובים!$Q$1)+(AWS[Column1]=חישובים!$Q$2), ROW(AWS[Column1])-MIN(ROW(AWS[Column1]))+1, ""), ROW(INDIRECT("1:"&COUNTIF(AWS[Column1],חישובים!$Q$1)+COUNTIF(AWS[Column1],חישובים!$Q$2)))), {3,4,5,6,27,2,23,21}) = 0, "", INDEX(AWS[], SMALL(IF((AWS[Column1]=חישובים!$Q$1)+(AWS[Column1]=חישובים!$Q$2), ROW(AWS[Column1])-MIN(ROW(AWS[Column1]))+1, ""), ROW(INDIRECT("1:"&COUNTIF(AWS[Column1],חישובים!$Q$1)+COUNTIF(AWS[Column1],חישובים!$Q$2)))), {3,4,5,6,27,2,23,21}) ), IF( AND(E4=חישובים!O3, E3=חישובים!N2), IF( INDEX(AWS_2[], SMALL(IF((AWS_2[Column1]=חישובים!$Q$1)+(AWS_2[Column1]=חישובים!$Q$2), ROW(AWS_2[Column1])-MIN(ROW(AWS_2[Column1]))+1, ""), ROW(INDIRECT("1:"&COUNTIF(AWS_2[Column1],חישובים!$Q$1)+COUNTIF(AWS_2[Column1],חישובים!$Q$2)))), {3,4,5,6,27,2,23,21}) = 0, "", INDEX(AWS_2[], SMALL(IF((AWS_2[Column1]=חישובים!$Q$1)+(AWS_2[Column1]=חישובים!$Q$2), ROW(AWS_2[Column1])-MIN(ROW(AWS_2[Column1]))+1, ""), ROW(INDIRECT("1:"&COUNTIF(AWS_2[Column1],חישובים!$Q$1)+COUNTIF(AWS_2[Column1],חישובים!$Q$2)))), {3,4,5,6,27,2,23,21}) ), IF( AND(E4=חישובים!O2, E3=חישובים!N3), IF( INDEX(GCP[], SMALL(IF((GCP[Column1]=חישובים!$Q$1)+(GCP[Column1]=חישובים!$Q$2), ROW(GCP[Column1])-MIN(ROW(GCP[Column1]))+1, ""), ROW(INDIRECT("1:"&COUNTIF(GCP[Column1],חישובים!$Q$1)+COUNTIF(GCP[Column1],חישובים!$Q$2)))), {3,4,5,6,27,2,23,21}) = 0, "", INDEX(GCP[], SMALL(IF((GCP[Column1]=חישובים!$Q$1)+(GCP[Column1]=חישובים!$Q$2), ROW(GCP[Column1])-MIN(ROW(GCP[Column1]))+1, ""), ROW(INDIRECT("1:"&COUNTIF(GCP[Column1],חישובים!$Q$1)+COUNTIF(GCP[Column1],חישובים!$Q$2)))), {3,4,5,6,27,2,23,21}) ), IF( AND(E4=חישובים!O3, E3=חישובים!N3), IF( INDEX(GCP_2[], SMALL(IF((GCP_2[Column1]=חישובים!$Q$1)+(GCP_2[Column1]=חישובים!$Q$2), ROW(GCP_2[Column1])-MIN(ROW(GCP_2[Column1]))+1, ""), ROW(INDIRECT("1:"&COUNTIF(GCP_2[Column1],חישובים!$Q$1)+COUNTIF(GCP_2[Column1],חישובים!$Q$2)))), {3,4,5,6,27,2,23,21}) = 0, "", INDEX(GCP_2[], SMALL(IF((GCP_2[Column1]=חישובים!$Q$1)+(GCP_2[Column1]=חישובים!$Q$2), ROW(GCP_2[Column1])-MIN(ROW(GCP_2[Column1]))+1, ""), ROW(INDIRECT("1:"&COUNTIF(GCP_2[Column1],חישובים!$Q$1)+COUNTIF(GCP_2[Column1],חישובים!$Q$2)))), {3,4,5,6,27,2,23,21}) ), "Error" ) ) ) )} -> מספר בקרה ב CIS | C9: סוג הנכס | D9: סוג בקרת אבטחה | E9: תיאור | F9: בקרת ספק מומלצת | G9: מספר בקרה ספק ענן CIS | H9: סוג הבקרה | I9: מתקבל כברירת מחדל באזור הנחיתה הממשלתי
B10: - | C10: - | D10: - | E10: מיפוי ובקרה על נכסים ארגוניים | F10: - | G10: - | H10: - | I10: .
B11: 1.1 | C11: Devices | D11: Identify | E11: הקמה ותחזוקה של מיפוי נכסים ארגוניים מפורטים | F11: v | G11: 2.13 | H11: מערכת | I11: -
B12: 1.2 | C12: Devices | D12: Respond | E12: התייחס לנכסים לא מורשים | G12: - | H12: ארגוני | I12: -
B13: 1.3 | C13: Devices | D13: Detect | E13: השתמשו בכלי גילוי אקטיביים | G13: - | H13: ארגוני | I13: -
B14: 1.4 | C14: Devices | D14: Identify | E14: השתמש ברישום-Dynamic Host Configuration Protocol (DHCP) כדי לעדכן את מיפוי הנכסים הארגוניים | G14: - | H14: ארגוני | I14: -
B15: 1.5 | C15: Devices | D15: Detect | E15: השתמש בכלי גילוי נכסים פסיבי | G15: - | H15: ארגוני | I15: -
B16: - | C16: - | D16: - | E16: מיפוי ובקרת נכסי תוכנה | F16: - | G16: - | H16: - | I16: -
B17: 2.1 | C17: Applications | D17: Identify | E17: הקמה ותחזוקה של מיפוי תוכנה | G17: - | H17: ארגוני | I17: -
B18: 2.2 | C18: Applications | D18: Identify | E18: ודא כי התוכנה המורשית בארגון נתמכת על ידי היצרן | F18: v | G18: 4.12 | H18: מערכת | I18: -
B19: 2.3 | C19: Applications | D19: Respond | E19: קיים תוכנית לטיפול ברכיבי תוכנה לא מאושרים | G19: - | H19: ארגוני | I19: -
B20: 2.4 | C20: Applications | D20: Detect | E20: השתמש בכלי מיפוי תוכנה אוטומטיים | G20: - | H20: ארגוני | I20: -
B21: 2.5 | C21: Applications | D21: Protect | E21: ניהול רשימת תוכנות מאושרות | G21: - | H21: ארגוני | I21: -
B22: 2.6 | C22: Applications | D22: Protect | E22: ניהול רשימת ספריות קוד מאושרות | G22: - | H22: מערכת | I22: -
B23: 2.7 | C23: Applications | D23: Protect | E23: ניהול רשימת קטעי קוד וסקריפטים מאושרים | F23: v | G23: 6.3.1 | H23: מערכת | I23: -
A24: {=IFERROR(INDEX(#REF!, MATCH("Yes",#REF!, 0),0),"")} | B24: - | C24: - | D24: - | E24: הגנת מידע | F24: - | G24: - | H24: - | I24: -
A25: {=IFERROR(INDEX(#REF!, MATCH("Yes",#REF!, 0),0),"")} | B25: 3.1 | C25: Data | D25: Identify | E25: נדרש להקין ולתחזוק תהליך ניהול אבטחת מידע | G25: - | H25: מערכת | I25: -
B26: 3.2 | C26: Data | D26: Identify | E26: הקמה ותחזוקה של מיפוי נתונים | G26: - | H26: ארגוני | I26: -
B27: 3.3 | C27: Data | D27: Protect | E27: הגדר בקרת גישה לנתונים | F27: v | G27: 1.6 | H27: ארגוני | I27: v
B28: 3.3 | C28: Data | D28: Protect | E28: הגדר בקרת גישה לנתונים | F28: v | G28: 1.8 | H28: מערכת | I28: -
B29: 3.3 | C29: Data | D29: Protect | E29: הגדר בקרת גישה לנתונים | F29: v | G29: 1.9 | H29: מערכת | I29: -
B30: 3.3 | C30: Data | D30: Protect | E30: הגדר בקרת גישה לנתונים | F30: v | G30: 1.11 | H30: מערכת | I30: -
B31: 3.3 | C31: Data | D31: Protect | E31: הגדר בקרת גישה לנתונים | F31: v | G31: 2.3 | H31: מערכת | I31: -
B32: 3.3 | C32: Data | D32: Protect | E32: הגדר בקרת גישה לנתונים | F32: v | G32: 2.15 | H32: מערכת | I32: -
B33: 3.3 | C33: Data | D33: Protect | E33: הגדר בקרת גישה לנתונים | F33: v | G33: 4.9 | H33: ארגוני | I33: v
B34: 3.3 | C34: Data | D34: Protect | E34: הגדר בקרת גישה לנתונים | F34: v | G34: 5.1 | H34: ארגוני | I34: v
B35: 3.3 | C35: Data | D35: Protect | E35: הגדר בקרת גישה לנתונים | F35: v | G35: 5.2 | H35: ארגוני | I35: v
B36: 3.3 | C36: Data | D36: Protect | E36: הגדר בקרת גישה לנתונים | F36: v | G36: 6.1.2 | H36: מערכת | I36: -
B37: 3.3 | C37: Data | D37: Protect | E37: הגדר בקרת גישה לנתונים | F37: v | G37: 6.3.2 | H37: מערכת | I37: -
B38: 3.3 | C38: Data | D38: Protect | E38: הגדר בקרת גישה לנתונים | F38: v | G38: 6.3.7 | H38: מערכת | I38: -
... B41: 3.3 | C41: Data | D41: Protect | E41: הגדר בקרת גישה לנתונים | F41: v | G41: 7.1 | H41: מערכת | I41: v
B42: 3.4 | C42: Data | D42: Protect | E42: יש להגדיר אכיפת Data Ritention | G42: - | H42: ארגוני | I42: -
B43: 3.5 | C43: Data | D43: Protect | E43: יש לוודא השמדת מידע מאובטחת בסיום תקופת ה Ritention | G43: - | H43: ארגוני | I43: -
B44: 3.7 | C44: Data | D44: Identify | E44: הקמה ותחזוקה של תוכנית סיווג נתונים | G44: - | H44: ארגוני | I44: -
B45: 3.8 | C45: Data | D45: Identify | E45: הגדרת אופן זרימת נתונים | G45: - | H45: ארגוני | I45: -
B46: 3.1 | C46: Data | D46: Protect | E46: הצפנת נתונים רגישים בתנועה | F46: v | G46: 3.9 | H46: ארגוני | I46: v
B47: 3.1 | C47: Data | D47: Protect | E47: הצפנת נתונים רגישים בתנועה | F47: v | G47: 4.3 | H47: מערכת | I47: -
...

Sheet חישובים ונתונים
C1: אזהרה!!! שינוי מילים או מיקומי שדות ועדכון נוסחאות ישפיעו על תוצאות המחשבון נבנה על ידי אבא אקילוב | XFD1: נבנה על ידי אבא אקילוב
